Workbook

Sheet 8.1
A1: ތާވަލު 8.1: ހުށަހެޅިފައިވާ މައްސަލަތައް، 2011- 2015
A2: Table 8.1: LOGGED CASES FROM THE YEAR, 2011 - 2015
A3: Logged Cases | B3: 2008 | C3: 2009 | D3: 2011 | E3: 2012 | F3: 2013 | G3: 2014 | H3: 2015 | I3: ބެހިފައިވާ ގޮތް އިންސައްތައިން | J3: 2014އާއި އަޅާބަލާއިރު 2015ގައި އިތުރުވި މިންވަރު (%) | K3: ހުށަހެޅިފައިވާ މައްސަލަތައް
I4: % share 2015 | J4: % change over 2014
A5: Total | B5: 17674 | C5: 19259 | D5: =SUM(D6:D17) -> 17803 | E5: =SUM(E6:E17) -> 20512 | F5: =SUM(F6:F17) -> 21885 | G5: =SUM(G6:G17) -> 18193 | H5: 16363 | I5: =H5/$H$5*100 -> 100 | J5: =((H5-G5)/G5)*100 -> -10.058814 | K5: wlcmuj | V5: Theft | W5: =I6 -> 24.384282
A6: Theft | B6: 3903 | C6: 4007 | D6: 4734 | E6: 6571 | F6: 6683 | G6: 5080 | H6: 3990 | I6: =H6/$H$5*100 -> 24.384282 | J6: =((H6-G6)/G6)*100 -> -21.456693 | K6: ވައްކަން | V6: Drugs | W6: =I7 -> 12.497708
A7: Traffic accidents | B7: 3838 | C7: 3013 | D7: 2251 | E7: 1974 | F7: 1930 | G7: 2137 | H7: 2045 | I7: =H7/$H$5*100 -> 12.497708 | J7: =((H7-G7)/G7)*100 -> -4.3051006 | K7: ޓްރެފިކް | V7: Traffic accidents | W7: =I8 -> 12.699383
A8: Drugs | B8: 2484 | C8: 2366 | D8: 1823 | E8: 2534 | F8: 3965 | G8: 3140 | H8: 2078 | I8: =H8/$H$5*100 -> 12.699383 | J8: =((H8-G8)/G8)*100 -> -33.821656 | K8: މަސްތުވާތަކެތި | V8: Lost Items | W8: =I9 -> 10.493186
A9: Lost Items | B9: 1520 | C9: 2139 | D9: 1480 | E9: 1508 | F9: 1983 | G9: 2014 | H9: 1717 | I9: =H9/$H$5*100 -> 10.493186 | J9: =((H9-G9)/G9)*100 -> -14.746773 | K9: ގެއްލޭތަކެތި | V9: Assault | W9: =I10 -> 5.7141111
A10: Assault | B10: 1602 | C10: 2000 | D10: 1320 | E10: 1264 | F10: 1289 | G10: 1062 | H10: 935 | I10: =H10/$H$5*100 -> 5.7141111 | J10: =((H10-G10)/G10)*100 -> -11.958569 | K10: މާރާމާރީ | V10: Robbery | W10: =I11 -> 3.2634602
A11: Vandalism | B11: 648 | C11: 902 | D11: 775 | E11: 880 | F11: 728 | G11: 520 | H11: 534 | I11: =H11/$H$5*100 -> 3.2634602 | J11: =((H11-G11)/G11)*100 -> 2.6923077 | K11: މުދަލަށް ގެއްލުންދިނުން | V11: Vandalism | W11: =I12 -> 3.3245737
A12: Robbery | B12: 596 | C12: 589 | D12: 718 | E12: 972 | F12: 729 | G12: 620 | H12: 544 | I12: =H12/$H$5*100 -> 3.3245737 | J12: =((H12-G12)/G12)*100 -> -12.258065 | K12: ފޭރުން | V12: Sexual offences | W12: =I13 -> 3.2451262
A13: Sexual offences | B13: 455 | C13: 563 | D13: 642 | E13: 577 | F13: 573 | G13: 475 | H13: 531 | I13: =H13/$H$5*100 -> 3.2451262 | J13: =((H13-G13)/G13)*100 -> 11.789474 | K13: ބަދުއަޙްލާޤީ | V13: Embezzelment | W13: =I14 -> 4.5285094
A14: Embezzelment | B14: 313 | C14: 391 | D14: 364 | E14: 311 | F14: 391 | G14: 377 | H14: 741 | I14: =H14/$H$5*100 -> 4.5285094 | J14: =((H14-G14)/G14)*100 -> 96.551724 | K14: މަކަރާއި ޙީލަތް | V14: Domestic violence | W14: =I15 -> 2.0656359
A15: Domestic violence | B15: 172 | C15: 156 | D15: 146 | E15: 179 | F15: 207 | G15: 186 | H15: 338 | I15: =H15/$H$5*100 -> 2.0656359 | J15: =((H15-G15)/G15)*100 -> 81.72043 | K15: އާއިލީ | V15: Counterfiet and forgery | W15: =I16 -> 0.55613274
A16: Counterfiet and forgery | B16: 98 | C16: 133 | D16: 136 | E16: 126 | F16: 97 | G16: 77 | H16: 91 | I16: =H16/$H$5*100 -> 0.55613274 | J16: =((H16-G16)/G16)*100 -> 18.181818 | K16: ވަގުފައިސާ އަދި ފޯރޖްކުރުން | V16: Others | W16: =I17 -> 17.227892
A17: Others | B17: 1763 | C17: 2399 | D17: 3414 | E17: 3616 | F17: 3310 | G17: 2505 | H17: 2819 | I17: =H17/$H$5*100 -> 17.227892 | J17: =((H17-G17)/G17)*100 -> 12.53493 | K17: އެހެނިހެން
A18: Source: Maldives Police Service | K18: csivrws csilop cscviDclOm :Ivcaed utWmUluAwm
W21: 2010 | X21: 2011 | Y21: 2012 | Z21: 2013 | AA21: 2014 | AB21: 2015
V22: Theft | W22: -0.14973796 | X22: 18.32042 | Y22: 38.804394 | Z22: 1.704459 | AA22: -23.986234 | AB22: =((H6-G6)/G6)*100 -> -21.456693
V23: Traffic accidents | W23: -19.349486 | X23: -7.3662551 | Y23: -12.305642 | Z23: -2.2289767 | AA23: 10.725389 | AB23: =((H7-G7)/G7)*100 -> -4.3051006
V24: Drugs | W24: -31.656805 | X24: 12.739641 | Y24: 39.001646 | Z24: 56.471981 | AA24: -20.807062 | AB24: =((H8-G8)/G8)*100 -> -33.821656
V25: Lost Items | W25: -19.915849 | X25: -13.601868 | Y25: 1.8918919 | Z25: 31.498674 | AA25: 1.5632879 | AB25: =((H9-G9)/G9)*100 -> -14.746773
V26: Assault | W26: -23.7 | X26: -13.499345 | Y26: -4.2424242 | Z26: 1.9778481 | AA26: -17.610551 | AB26: =((H10-G10)/G10)*100 -> -11.958569

Sheet 8.2
A1: ތާވަލު 8.2: މާލެ އަދި އަތޮޅުތަކުން ހުށަހެޅިފައިވާ މައްސަލަތަކުގެ ޢަދަދު އަދި ބާވަތް، 2014- 2015
A2: TABLE 8.2 : NUMBER OF LOGGED CASES BY LOCALITY & TYPE OF CASES, 2014 - 2015
A3: Type of case | B3: 2014 | E3: 2015 | H3: ކުރީ އަހަރާއި އަޅާ ބަލާއިރު އިތުރުވި މިންވަރު | K3: ހުށަހެޅިފައިވާ މައްސަލަތައް
H4: % change over 2014
B5: ރާއްޖެ | C5: މާލެ | D5: އަތޮޅުތައް | E5: ރާއްޖެ | F5: މާލެ | G5: އަތޮޅުތައް | H5: ރާއްޖެ | I5: މާލެ | J5: އަތޮޅުތައް
B6: Republic | C6: Male' | D6: Atolls | E6: Republic | F6: Male' | G6: Atolls | H6: Republic | I6: Male' | J6: Atolls
A7: Total | B7: =SUM(C7:D7) -> 18193 | C7: =SUM(C8:C19) -> 12660 | D7: =SUM(D8:D19) -> 5533 | E7: =SUM(F7:G7) -> 16363 | F7: 11289 | G7: 5074 | H7: =(E7-B7)/B7*100 -> -10.058814 | I7: =(F7-C7)/C7*100 -> -10.829384 | J7: =(G7-D7)/D7*100 -> -8.2956805 | K7: wlcmuj
A8: Theft | B8: =SUM(C8:D8) -> 5080 | C8: 3662 | D8: 1418 | E8: =SUM(F8:G8) -> 3990 | F8: 2844 | G8: 1146 | H8: =(E8-B8)/B8*100 -> -21.456693 | I8: =(F8-C8)/C8*100 -> -22.33752 | J8: =(G8-D8)/D8*100 -> -19.181946 | K8: ވައްކަން
A9: Traffic Accidents | B9: =SUM(C9:D9) -> 2137 | C9: 1993 | D9: 144 | E9: =SUM(F9:G9) -> 2045 | F9: 1934 | G9: 111 | H9: =(E9-B9)/B9*100 -> -4.3051006 | I9: =(F9-C9)/C9*100 -> -2.9603613 | J9: =(G9-D9)/D9*100 -> -22.916667 | K9: ޓްރެފިކް އެކްސިޑެންޓްސް
A10: Drugs | B10: =SUM(C10:D10) -> 3140 | C10: 1906 | D10: 1234 | E10: =SUM(F10:G10) -> 2078 | F10: 1192 | G10: 886 | H10: =(E10-B10)/B10*100 -> -33.821656 | I10: =(F10-C10)/C10*100 -> -37.460651 | J10: =(G10-D10)/D10*100 -> -28.200972 | K10: މަސްތުވާތަކެތި
A11: Lost items | B11: =SUM(C11:D11) -> 2014 | C11: 1611 | D11: 403 | E11: =SUM(F11:G11) -> 1717 | F11: 1369 | G11: 348 | H11: =(E11-B11)/B11*100 -> -14.746773 | I11: =(F11-C11)/C11*100 -> -15.021726 | J11: =(G11-D11)/D11*100 -> -13.647643 | K11: ގެއްލޭތަކެތި
A12: Assault | B12: =SUM(C12:D12) -> 1062 | C12: 494 | D12: 568 | E12: =SUM(F12:G12) -> 935 | F12: 406 | G12: 529 | H12: =(E12-B12)/B12*100 -> -11.958569 | I12: =(F12-C12)/C12*100 -> -17.813765 | J12: =(G12-D12)/D12*100 -> -6.8661972 | K12: މާރާމާރީ
A13: Vandalism | B13: =SUM(C13:D13) -> 520 | C13: 277 | D13: 243 | E13: =SUM(F13:G13) -> 534 | F13: 291 | G13: 243 | H13: =(E13-B13)/B13*100 -> 2.6923077 | I13: =(F13-C13)/C13*100 -> 5.0541516 | J13: =(G13-D13)/D13*100 -> 0 | K13: މުދަލަށް ގެއްލުންދިނުން
A14: Robbery | B14: =SUM(C14:D14) -> 620 | C14: 561 | D14: 59 | E14: =SUM(F14:G14) -> 544 | F14: 495 | G14: 49 | H14: =(E14-B14)/B14*100 -> -12.258065 | I14: =(F14-C14)/C14*100 -> -11.764706 | J14: =(G14-D14)/D14*100 -> -16.949153 | K14: ފޭރުން
A15: Sexual offences | B15: =SUM(C15:D15) -> 475 | C15: 136 | D15: 339 | E15: =SUM(F15:G15) -> 531 | F15: 147 | G15: 384 | H15: =(E15-B15)/B15*100 -> 11.789474 | I15: =(F15-C15)/C15*100 -> 8.0882353 | J15: =(G15-D15)/D15*100 -> 13.274336 | K15: ބަދުއަޙްލާޤީ
A16: Embezzelment | B16: =SUM(C16:D16) -> 377 | C16: 288 | D16: 89 | E16: =SUM(F16:G16) -> 741 | F16: 612 | G16: 129 | H16: =(E16-B16)/B16*100 -> 96.551724 | I16: =(F16-C16)/C16*100 -> 112.5 | J16: =(G16-D16)/D16*100 -> 44.94382 | K16: މަކަރާއި ޙީލަތް
A17: Domestic violence | B17: =SUM(C17:D17) -> 186 | C17: 101 | D17: 85 | E17: =SUM(F17:G17) -> 338 | F17: 139 | G17: 199 | H17: =(E17-B17)/B17*100 -> 81.72043 | I17: =(F17-C17)/C17*100 -> 37.623762 | J17: =(G17-D17)/D17*100 -> 134.11765 | K17: އާއިލީ
A18: Counterfiet and forgery | B18: =SUM(C18:D18) -> 77 | C18: 65 | D18: 12 | E18: =SUM(F18:G18) -> 91 | F18: 79 | G18: 12 | H18: =(E18-B18)/B18*100 -> 18.181818 | I18: =(F18-C18)/C18*100 -> 21.538462 | J18: =(G18-D18)/D18*100 -> 0 | K18: ވަގުފައިސާ އަދި ފޯރޖްކުރުން
A19: Others | B19: =SUM(C19:D19) -> 2505 | C19: =SUM(C20:C30) -> 1566 | D19: =SUM(D20:D30) -> 939 | E19: =SUM(F19:G19) -> 2819 | F19: 1781 | G19: 1038 | H19: =(E19-B19)/B19*100 -> 12.53493 | I19: =(F19-C19)/C19*100 -> 13.729246 | J19: =(G19-D19)/D19*100 -> 10.543131 | K19: އެހެނިހެން
A20: Threatening | B20: =SUM(C20:D20) -> 592 | C20: 329 | D20: 263 | E20: =SUM(F20:G20) -> 532 | F20: 272 | G20: 260 | H20: =(E20-B20)/B20*100 -> -10.135135 | I20: =(F20-C20)/C20*100 -> -17.325228 | J20: =(G20-D20)/D20*100 -> -1.1406844 | K20: ބިރުދެއްކުން
A21: Fire incidents | B21: =SUM(C21:D21) -> 57 | C21: 22 | D21: 35 | E21: =SUM(F21:G21) -> 61 | F21: 31 | G21: 30 | H21: =(E21-B21)/B21*100 -> 7.0175439 | I21: =(F21-C21)/C21*100 -> 40.909091 | J21: =(G21-D21)/D21*100 -> -14.285714 | K21: އަލިފާނުގެ ހާދިސާ
A22: Environmental offences | B22: =SUM(C22:D22) -> 52 | C22: 4 | D22: 48 | E22: =SUM(F22:G22) -> 25 | F22: 8 | G22: 17 | H22: =(E22-B22)/B22*100 -> -51.923077 | I22: =(F22-C22)/C22*100 -> 100 | J22: =(G22-D22)/D22*100 -> -64.583333 | K22: ތިމާވެއްޓާއި ގުޅުންހުރި މައްސަލަތައް
A23: Illegal immigration | B23: =SUM(C23:D23) -> 40 | C23: 26 | D23: 14 | E23: =SUM(F23:G23) -> 38 | F23: 20 | G23: 18 | H23: =(E23-B23)/B23*100 -> -5 | I23: =(F23-C23)/C23*100 -> -23.076923 | J23: =(G23-D23)/D23*100 -> 28.571429 | K23: ރާއްޖެއަށް ނުވަތަ ރާއްޖޭގެ ސަރަހައްދަކަށް ޤަވާއިދާއި ހިލާފަށް ވަނުން
A24: Arson | B24: =SUM(C24:D24) -> 42 | C24: 5 | D24: 37 | E24: =SUM(F24:G24) -> 60 | F24: 14 | G24: 46 | H24: =(E24-B24)/B24*100 -> 42.857143 | I24: =(F24-C24)/C24*100 -> 180 | J24: =(G24-D24)/D24*100 -> 24.324324 | K24: ހުޅުޖެހުން
A25: Obstruction of Justice | B25: =SUM(C25:D25) -> 166 | C25: 70 | D25: 96 | E25: =SUM(F25:G25) -> 145 | F25: 79 | G25: 66 | H25: =(E25-B25)/B25*100 -> -12.650602 | I25: =(F25-C25)/C25*100 -> 12.857143 | J25: =(G25-D25)/D25*100 -> -31.25 | K25: ފުލުހުންގެ ވާޖިބަށް ހުރަސް އެޅުން
A26: Illegally entering households | B26: =SUM(C26:D26) -> 65 | C26: 39 | D26: 26 | E26: =SUM(F26:G26) -> 96 | F26: 58 | G26: 38 | H26: =(E26-B26)/B26*100 -> 47.692308 | I26: =(F26-C26)/C26*100 -> 48.717949 | J26: =(G26-D26)/D26*100 -> 46.153846 | K26: ޤަވާއިދާއި ޚިލާފަށް ގޯތިގެދޮރަށް ވަނުން
A27: Sudden death | B27: =SUM(C27:D27) -> 5 | C27: 3 | D27: 2 | E27: =SUM(F27:G27) -> 6 | F27: 0 | G27: 6 | H27: =(E27-B27)/B27*100 -> 20 | I27: =(F27-C27)/C27*100 -> -100 | J27: =(G27-D27)/D27*100 -> 200 | K27: ކުއްލި މަރު
A28: Attempt to suicide | B28: =SUM(C28:D28) -> 42 | C28: 22 | D28: 20 | E28: =SUM(F28:G28) -> 62 | F28: 29 | G28: 33 | H28: =(E28-B28)/B28*100 -> 47.619048 | I28: =(F28-C28)/C28*100 -> 31.818182 | J28: =(G28-D28)/D28*100 -> 65 | K28: އަމިއްލައަށް މަރުވާން އުޅުން
A29: Unlawful posession of weapons | B29: =SUM(C29:D29) -> 77 | C29: 48 | D29: 29 | E29: =SUM(F29:G29) -> 45 | F29: 23 | G29: 22 | H29: =(E29-B29)/B29*100 -> -41.558442 | I29: =(F29-C29)/C29*100 -> -52.083333 | J29: =(G29-D29)/D29*100 -> -24.137931 | K29: ހަތިޔާރު ގެންގުޅުން
A30: Others | B30: =SUM(C30:D30) -> 1367 | C30: 998 | D30: 369 | E30: =SUM(F30:G30) -> 1749 | F30: 1247 | G30: 502 | H30: =(E30-B30)/B30*100 -> 27.944404 | I30: =(F30-C30)/C30*100 -> 24.9499 | J30: =(G30-D30)/D30*100 -> 36.04336 | K30: އެހެނިހެން
A31: Source: Maldives Police Service | K31: csivrws csilop cscviDclOm :Ivcaed utWmUluAwm

Sheet 8.3
A1: ތާވަލު 8.3: އެކި އަތޮޅުތަކުން ހުށަހެޅިފައިވާ މައްސަލަތަކުގެ އަދަދު، 2010- 2015
A2: TABLE: 8.3: NUMBER OF LOGGED CASES BY ATOLL, 2010 - 2015
A3: Locality | B3: 2010 | C3: 2011 | D3: 2012 | E3: 2013 | F3: 2014 | G3: 2015 | I3: ކުރީ އަހަރާއި އަޅާ | J3: ތަން
I4: ބަލާއިރު އިތުރުވި މިންވަރު
I5: % change over 2014
A6: Republic | B6: =SUM(B7:B8) -> 16994 | C6: =SUM(C7:C8) -> 17803 | D6: =SUM(D7:D8) -> 20512 | E6: =SUM(E7:E8) -> 21885 | F6: =SUM(F7:F8) -> 18193 | G6: =SUM(G7:G8) -> 16363 | I6: =((G6-F6)/F6)*100 -> -10.058814 | J6: ejcaWriLum
A7: Male' | B7: 12238 | C7: 11907 | D7: 14555 | E7: 15284 | F7: 12660 | G7: 11289 | I7: =((G7-F7)/F7)*100 -> -10.829384 | J7: elWm
A8: Atolls | B8: =SUM(B9:B28) -> 4756 | C8: =SUM(C9:C28) -> 5896 | D8: =SUM(D9:D28) -> 5957 | E8: =SUM(E9:E28) -> 6601 | F8: =SUM(F9:F29) -> 5533 | G8: =SUM(G9:G28) -> 5074 | I8: =((G8-F8)/F8)*100 -> -8.2956805 | J8: އަތޮޅުތައް
A9: HA | B9: 269 | C9: 246 | D9: 236 | E9: 236 | F9: 210 | G9: 210 | I9: =((G9-F9)/F9)*100 -> 0 | J9: ah
A10: HDh | B10: 575 | C10: 726 | D10: 630 | E10: 608 | F10: 568 | G10: 394 | I10: =((G10-F10)/F10)*100 -> -30.633803 | J10: dh
A11: Sh | B11: 164 | C11: 186 | D11: 171 | E11: 138 | F11: 155 | G11: 145 | I11: =((G11-F11)/F11)*100 -> -6.4516129 | J11: S
A12: N | B12: 199 | C12: 232 | D12: 268 | E12: 260 | F12: 221 | G12: 142 | I12: =((G12-F12)/F12)*100 -> -35.746606 | J12: n
A13: R | B13: 205 | C13: 250 | D13: 220 | E13: 229 | F13: 242 | G13: 259 | I13: =((G13-F13)/F13)*100 -> 7.0247934 | J13: r
A14: B | B14: 173 | C14: 218 | D14: 245 | E14: 157 | F14: 167 | G14: 138 | I14: =((G14-F14)/F14)*100 -> -17.365269 | J14: b
A15: Lh | B15: 182 | C15: 185 | D15: 253 | E15: 208 | F15: 245 | G15: 235 | I15: =((G15-F15)/F15)*100 -> -4.0816327 | J15: L
A16: K | B16: 228 | C16: 363 | D16: 372 | E16: 281 | F16: 277 | G16: 369 | I16: =((G16-F16)/F16)*100 -> 33.212996 | J16: k
A17: AA | B17: 114 | C17: 111 | D17: 103 | E17: 135 | F17: 91 | G17: 121 | I17: =((G17-F17)/F17)*100 -> 32.967033 | J17: aa
A18: ADh | B18: 141 | C18: 187 | D18: 151 | E18: 500 | F18: 284 | G18: 252 | I18: =((G18-F18)/F18)*100 -> -11.267606 | J18: da
A19: V | B19: 15 | C19: 18 | D19: 27 | E19: 19 | F19: 32 | G19: 39 | I19: =((G19-F19)/F19)*100 -> 21.875 | J19: v
A20: M | B20: 83 | C20: 105 | D20: 108 | E20: 77 | F20: 64 | G20: 64 | I20: =((G20-F20)/F20)*100 -> 0 | J20: m
... A28: S | B28: 840 | C28: 996 | D28: 1105 | E28: 1349 | F28: 988 | G28: 903 | I28: =((G28-F28)/F28)*100 -> -8.6032389 | J28: s
A29: N/A | B29: - | C29: - | D29: - | E29: - | F29: 6 | G29: 0 | H29: 6 | I29: =((G29-F29)/F29)*100 -> -100
A30: Note: N/A - Not Applicable | J30: csivrws csilop cscviDclOm :Ivcaed utWmUluAwm
A31: Source: Maldives Police Service

Sheet 8.4
A1: ތާވަލު 8.4: އަތޮޅުތަކުން ހުށަހެޅިފައިވާ މައްސަލަތައް، 2015
A2: Table 8.4 : LOGGED CASES BY TYPE AND ATOLL, 2015
A3: Type of case | B3: ޖުމްލަ | C3: ah | D3: dh | E3: S | F3: n | G3: r | H3: b | I3: L | J3: k | K3: aa | L3: da | M3: v | N3: m | O3: f | P3: d | Q3: t | R3: l | S3: ag | T3: dg | U3: N | V3: s | W3: ހުށަހެޅިފައިވާ މައްސަލަތައް
B4: Total | C4: HA | D4: HDh | E4: Sh | F4: N | G4: R | H4: B | I4: Lh | J4: K | K4: AA | L4: ADh | M4: V | N4: M | O4: F | P4: Dh | Q4: Th | R4: L | S4: GA | T4: GDh | U4: Gn | V4: S
A5: Total | B5: =SUM(B6:B17) -> 5074 | C5: =SUM(C6:C17) -> 210 | D5: =SUM(D6:D17) -> 394 | E5: =SUM(E6:E17) -> 145 | F5: =SUM(F6:F17) -> 142 | G5: =SUM(G6:G17) -> 259 | H5: =SUM(H6:H17) -> 138 | I5: =SUM(I6:I17) -> 235 | ... V5: =SUM(V6:V17) -> 903 | W5: ޖުމްލަ
A6: Theft | B6: =SUM(C6:V6) -> 1146 | C6: 41 | D6: 94 | E6: 28 | F6: 28 | G6: 53 | H6: 31 | I6: 53 | J6: 78 | K6: 16 | L6: 42 | M6: 4 | N6: 13 | O6: 14 | P6: 9 | Q6: 27 | R6: 65 | S6: 98 | T6: 103 | U6: 95 | V6: 254 | W6: ވައްކަން
A7: Traffic Accidents | B7: =SUM(C7:V7) -> 111 | C7: 2 | D7: 14 | E7: 0 | F7: 1 | G7: 7 | H7: 1 | I7: 3 | J7: 3 | K7: 0 | L7: 3 | M7: 0 | N7: 1 | O7: 0 | P7: 0 | Q7: 0 | R7: 5 | S7: 5 | T7: 6 | U7: 8 | V7: 52 | W7: ޓްރެފިކް އެކްސިޑެންޓްސް
A8: Drugs | B8: =SUM(C8:V8) -> 886 | C8: 19 | D8: 51 | E8: 22 | F8: 40 | G8: 49 | H8: 7 | I8: 53 | J8: 79 | K8: 19 | L8: 35 | M8: 3 | N8: 16 | O8: 3 | P8: 11 | Q8: 40 | R8: 70 | S8: 84 | T8: 77 | U8: 68 | V8: 140 | W8: މަސްތުވާތަކެތި
A9: Lost items | B9: =SUM(C9:V9) -> 348 | C9: 12 | D9: 28 | E9: 10 | F9: 5 | G9: 8 | H9: 8 | I9: 15 | J9: 49 | K9: 9 | L9: 54 | M9: 4 | N9: 3 | O9: 9 | P9: 7 | Q9: 4 | R9: 11 | S9: 16 | T9: 18 | U9: 29 | V9: 49 | W9: ގެއްލޭތަކެތި
A10: Assault | B10: =SUM(C10:V10) -> 529 | C10: 16 | D10: 39 | E10: 11 | F10: 15 | G10: 36 | H10: 13 | I10: 26 | J10: 32 | K10: 12 | L10: 24 | M10: 4 | N10: 3 | O10: 11 | P10: 5 | Q10: 15 | R10: 46 | S10: 55 | T10: 47 | U10: 34 | V10: 85 | W10: މާރާމާރީ
A11: Vandalism | B11: =SUM(C11:V11) -> 243 | C11: 11 | D11: 23 | E11: 11 | F11: 7 | G11: 11 | H11: 7 | I11: 10 | J11: 9 | K11: 3 | L11: 9 | M11: 3 | N11: 1 | O11: 7 | P11: 8 | Q11: 5 | R11: 12 | S11: 22 | T11: 14 | U11: 16 | V11: 54 | W11: މުދަލަށް ގެއްލުންދިނުން
A12: Robbery | B12: =SUM(C12:V12) -> 49 | C12: 0 | D12: 11 | E12: 0 | F12: 0 | G12: 0 | H12: 1 | I12: 0 | J12: 2 | K12: 1 | L12: 0 | M12: 0 | N12: 0 | O12: 0 | P12: 0 | Q12: 0 | R12: 1 | S12: 6 | T12: 3 | U12: 7 | V12: 17 | W12: ފޭރުން
A13: Sexual offences | B13: =SUM(C13:V13) -> 384 | C13: 31 | D13: 28 | E13: 16 | F13: 10 | G13: 26 | H13: 12 | I13: 17 | J13: 28 | K13: 19 | L13: 12 | M13: 5 | N13: 4 | O13: 7 | P13: 6 | Q13: 7 | R13: 35 | S13: 32 | T13: 27 | U13: 18 | V13: 44 | W13: ބަދުއަޙްލާޤީ
A14: Embezzelment | B14: =SUM(C14:V14) -> 129 | C14: 13 | D14: 18 | E14: 9 | F14: 1 | G14: 6 | H14: 4 | I14: 8 | J14: 7 | K14: 0 | L14: 6 | M14: 1 | N14: 1 | O14: 2 | P14: 2 | Q14: 2 | R14: 7 | S14: 4 | T14: 6 | U14: 6 | V14: 26 | W14: މަކަރާއި ޙީލަތް
A15: Domestic violence | B15: =SUM(C15:V15) -> 199 | C15: 7 | D15: 15 | E15: 3 | F15: 4 | G15: 12 | H15: 7 | I15: 16 | J15: 11 | K15: 12 | L15: 6 | M15: 1 | N15: 3 | O15: 7 | P15: 3 | Q15: 5 | R15: 18 | S15: 12 | T15: 17 | U15: 8 | V15: 32 | W15: އާއިލީ
A16: Counterfiet | B16: =SUM(C16:V16) -> 12 | C16: 1 | D16: 0 | E16: 1 | F16: 0 | G16: 0 | H16: 0 | I16: 1 | J16: 0 | K16: 0 | L16: 0 | M16: 0 | N16: 1 | O16: 0 | P16: 0 | Q16: 0 | R16: 3 | S16: 0 | T16: 1 | U16: 1 | V16: 3 | W16: ވަގުފައިސާ
A17: Others | B17: =SUM(C17:V17) -> 1038 | C17: 57 | D17: 73 | E17: 34 | F17: 31 | G17: 51 | H17: 47 | I17: 33 | J17: 71 | K17: 30 | L17: 61 | M17: 14 | N17: 18 | O17: 12 | P17: 12 | Q17: 31 | R17: 90 | S17: 76 | T17: 75 | U17: 75 | V17: 147 | W17: އެހެނިހެން
A18: Source: Maldives Police Service | W18: csivrws csilop cscviDclOm :Ivcaed utWmUluAwm
A50: Theft | B50: 1146
A51: Drugs | B51: 111
A52: Assault | B52: 886
A53: Lost items | B53: 348
A54: Sexual offences | B54: 529
A55: Vandalism | B55: 243
A56: Traffic Accidents | B56: 49
A57: Embezzelment | B57: 384
A58: Domestic violence | B58: 129
A59: Robbery | B59: 199
A60: Counterfiet | B60: 12
A61: Others | B61: 1038

Sheet 8.5
A1: 2015 - 2009 ,cawtwlwscawm WviawfiLehwSuh : 8.5 ulwvWt
A2: Table 8.5: LOGGED CASES 2009 - 2015
A4: Number of cases logged | B4: 2009 | C4: 2010 | D4: 2011 | E4: 2012 | F4: 2013 | G4: 2014 | H4: 2015 | I4: cawtwlwscawm WviwފiLehwSuh
A5: Total | B5: =SUM(B6:B17) -> 19259 | C5: =SUM(C6:C17) -> 16994 | D5: =SUM(D6:D17) -> 17803 | E5: =SUM(E6:E17) -> 20512 | F5: =SUM(F6:F17) -> 21885 | G5: =SUM(G6:G17) -> 18193 | H5: =SUM(H6:H17) -> 16363 | I5: wlcmuj
A6: January | B6: 1834 | C6: 1495 | D6: 1490 | E6: 1688 | F6: 1676 | G6: 2011 | H6: 1371 | I6: ޖެނުއަރީ
A7: February | B7: 1601 | C7: 1327 | D7: 1404 | E7: 1423 | F7: 1597 | G7: 1552 | H7: 1414 | I7: ފެބްރުއަރީ
A8: March | B8: 1877 | C8: 1516 | D8: 1735 | E8: 1578 | F8: 1952 | G8: 1798 | H8: 1441 | I8: މާރޗް
A9: April | B9: 1701 | C9: 1621 | D9: 1477 | E9: 1959 | F9: 1796 | G9: 1650 | H9: 1271 | I9: އޭޕްރިލް
A10: May | B10: 1556 | C10: 1493 | D10: 1473 | E10: 1621 | F10: 1740 | G10: 1640 | H10: 1332 | I10: މެއި
A11: June | B11: 1663 | C11: 1366 | D11: 1505 | E11: 1668 | F11: 1942 | G11: 1489 | H11: 1263 | I11: ޖޫން
A12: July | B12: 1597 | C12: 1253 | D12: 1300 | E12: 1773 | F12: 2005 | G12: 1412 | H12: 1326 | I12: ޖުލައި
A13: August | B13: 1433 | C13: 1510 | D13: 1464 | E13: 2001 | F13: 2007 | G13: 1380 | H13: 1609 | I13: އޯގަސްޓް
A14: September | B14: 1699 | C14: 1395 | D14: 1460 | E14: 1732 | F14: 1833 | G14: 1245 | H14: 1428 | I14: ސެޕްޓެމްބަރ
A15: October | B15: 1574 | C15: 1517 | D15: 1712 | E15: 1704 | F15: 1727 | G15: 1497 | H15: 1369 | I15: އޮކްޓޯބަރ
A16: November | B16: 1387 | C16: 1252 | D16: 1374 | E16: 1724 | F16: 1706 | G16: 1349 | H16: 1285 | I16: ނޮވެމްބަރ
A17: December | B17: 1337 | C17: 1249 | D17: 1409 | E17: 1641 | F17: 1904 | G17: 1170 | H17: 1254 | I17: ޑިސެމްބަރ
A18: Source: Maldives Police Service | I18: csivrws csilop cscviDclOm :Ivcaed utWmUluAwm

Sheet 8.6
A2: ތާވަލު 8.6: 1992 އިން 2015 ށް މައްސަލަ ހުށަހެޅުމުން އައިގޮތް
A3: Table 8.6: TREND SHOWING LOGGED CASES, 1992 - 2015
A5: Year | B5: No. of Cases Logged
A6: އަހަރު | B6: ހުށަހެޅުނު އަދަދު
A7: 1992 | B7: 3843
A8: 1993 | B8: 5067
A9: 1994 | B9: 5344
A10: 1995 | B10: 5449
A11: 1996 | B11: 5287
A12: 1997 | B12: 6979
A13: 1998 | B13: 6266
A14: 1999 | B14: 4586
A15: 2000 | B15: 4567
A16: 2001 | B16: 6417
A17: 2002 | B17: 7045
A18: 2003 | B18: 9085
... A29: 2014 | B29: 18193
A30: 2015 | B30: ='8.5'!H5 -> 16363
A31: Source: Maldives Police Service | B31: މަޢުލޫމާތު ދެއްވީ: މޯލްޑިވްސް ޕޮލިސް ސަރވިސް

Sheet 8.7
A1: ތާވަލު 8.7: ހުށަހެޅިފައިވާ ވައްކަމުގެ މައްސަލަތަކުގެ ބާވަތް، 2011- 2015
A2: Table 8.7: THEFT CASES LOGGED BY TYPE, 2011 - 2015
A3: Type | B3: 2011 | C3: 2012 | D3: 2013 | E3: 2014 | F3: 2015 | H3: ކުރީ އަހަރާއި އަޅާ | I3: އިންސައްތަ | J3: މައްސަލައިގެ ބާވަތް
H4: ބަލާއިރު އިތުރުވި މިންވަރު | I4: Percenatge share
H5: %change over 2014 | I5: 2015
A6: Total | B6: =SUM(B7:B13) -> 4734 | C6: =SUM(C7:C13) -> 6571 | D6: =SUM(D7:D13) -> 6683 | E6: =SUM(E7:E13) -> 5080 | F6: =SUM(F7:F13) -> 3990 | H6: =((F6-E6)/E6*100) -> -21.456693 | I6: =F6/$F$6*100 -> 100
A7: Theft from places (not by forced entry) | B7: 2194 | C7: 3099 | D7: 3285 | E7: 2275 | F7: 1382 | H7: =((F7-E7)/E7*100) -> -39.252747 | I7: =F7/$F$6*100 -> 34.636591 | J7: ތަންތަނުން ކޮށްފައިވާ ވައްކަން (ފަޅާލައިގެންނޫން ގޮތްގޮތަށް)
A8: Vehicles | B8: 913 | C8: 1379 | D8: 1017 | E8: 602 | F8: 651 | H8: =((F8-E8)/E8*100) -> 8.1395349 | I8: =F8/$F$6*100 -> 16.315789 | J8: ދުއްވާތަކެތީގެ ވައްކަން
A9: Mobile phones | B9: 643 | C9: 865 | D9: 1022 | E9: 817 | F9: 807 | H9: =((F9-E9)/E9*100) -> -1.2239902 | I9: =F9/$F$6*100 -> 20.225564 | J9: މޯބަލް ފޯން
A10: Money | B10: 200 | C10: 278 | D10: 324 | E10: 258 | F10: 285 | H10: =((F10-E10)/E10*100) -> 10.465116 | I10: =F10/$F$6*100 -> 7.1428571 | J10: ފައިސާ
A11: Electronic items (except mobile phones) | B11: 174 | C11: 235 | D11: 218 | E11: 238 | F11: 166 | H11: =((F11-E11)/E11*100) -> -30.252101 | I11: =F11/$F$6*100 -> 4.160401 | J11: އިލެކްޓްރޯނިކް ސާމާނު
A12: Theft from places (by forced entry) | B12: 111 | C12: 73 | D12: 130 | E12: 237 | F12: 219 | H12: =((F12-E12)/E12*100) -> -7.5949367 | I12: =F12/$F$6*100 -> 5.4887218 | J12: ފަޅާލައިގެންވަދެ ތަންތަނުން ކޮށްފައިވާ ވައްކަން
A13: Other theft | B13: 499 | C13: 642 | D13: 687 | E13: 653 | F13: 480 | H13: =((F13-E13)/E13*100) -> -26.493109 | I13: =F13/$F$6*100 -> 12.030075 | J13: އެހެނިހެން ވައްކަން
A14: Source: Maldives Police Service | J14: csivrws csilop cscviDclOm :Ivcaed utWmUluAwm

Sheet 8.8
A1: ތާވަލު 8.8: ހުށަހެޅިފައިވާ މަސްތުވާތަކެތީގެ މައްސަލަތަކާއި އަދި ބާވަތް، 2011- 2015
A2: Table 8.8: DRUG CASES LOGGED BY TYPE, 2011 - 2015
A3: Type | B3: 2011 | C3: 2012 | D3: 2013 | E3: 2014 | F3: 2015 | H3: ކުރީ އަހަރާއި އަޅާ | I3: 2015 | J3: މައްސަލައިގެ ބާވަތް
H4: ބަލާއިރު އިތުރުވި މިންވަރު | I4: އިންސައްތަ
H5: % change over 2014 | I5: Percenatge share
A6: Total | B6: =B7+B14+B21 -> 1823 | C6: =C7+C14+C21 -> 2534 | D6: =D7+D14+D21 -> 3965 | E6: =E7+E14+E21 -> 3140 | F6: =F7+F14+F21 -> 2078 | H6: =((F6-E6)/E6*100) -> -33.821656 | I6: =F6/F6*100 -> 100 | J6: ޖުމްލަ
A7: Drugs | B7: =SUM(B8:B13) -> 1618 | C7: =SUM(C8:C13) -> 2349 | D7: =SUM(D8:D13) -> 3444 | E7: =SUM(E8:E13) -> 2868 | F7: =SUM(F8:F13) -> 1912 | H7: =((F7-E7)/E7*100) -> -33.333333 | I7: =F7/$F$6*100 -> 92.01155 | J7: މަސްތުވާތަކެތީގެ މައްސަލަތައް
A8: Use | B8: 660 | C8: 1374 | D8: 2139 | E8: 2036 | F8: 1152 | H8: =((F8-E8)/E8*100) -> -43.418468 | I8: =F8/$F$6*100 -> 55.437921 | J8: ބޭނުންކުރުން
A9: Possession | B9: 842 | C9: 809 | D9: 833 | E9: 597 | F9: 578 | H9: =((F9-E9)/E9*100) -> -3.1825796 | I9: =F9/$F$6*100 -> 27.815207 | J9: ގެންގުޅުން
A10: Production | B10: - | C10: - | D10: 2 | E10: 7 | F10: 2 | H10: =((F10-E10)/E10*100) -> -71.428571 | I10: =F10/$F$6*100 -> 0.096246391 | J10: އުފެއްދުން
A11: Import | B11: 87 | C11: 106 | D11: 130 | E11: 98 | F11: 71 | H11: =((F11-E11)/E11*100) -> -27.55102 | I11: =F11/$F$6*100 -> 3.4167469 | J11: އެތެރެކުރުން
A12: Sale | B12: 29 | C12: 60 | D12: 38 | E12: 27 | F12: 73 | H12: =((F12-E12)/E12*100) -> 170.37037 | I12: =F12/$F$6*100 -> 3.5129933 | J12: ވިޔަފާރިކުރުން
A13: others | B13: - | C13: - | D13: 302 | E13: 103 | F13: 36 | H13: =((F13-E13)/E13*100) -> -65.048544 | I13: =F13/$F$6*100 -> 1.732435 | J13: އެހެނިހެން
A14: Alcohol | B14: =SUM(B15:B20) -> 182 | C14: =SUM(C15:C20) -> 166 | D14: =SUM(D15:D20) -> 502 | E14: =SUM(E15:E20) -> 262 | F14: =SUM(F15:F20) -> 161 | H14: =((F14-E14)/E14*100) -> -38.549618 | I14: =F14/$F$6*100 -> 7.7478345 | J14: ރަލުގެ މައްސަލަތައް
A15: Use | B15: 65 | C15: 71 | D15: 75 | E15: 62 | F15: 63 | H15: =((F15-E15)/E15*100) -> 1.6129032 | I15: =F15/$F$6*100 -> 3.0317613 | J15: ބޭނުންކުރުން
A16: Possession | B16: 96 | C16: 55 | D16: 359 | E16: 170 | F16: 55 | H16: =((F16-E16)/E16*100) -> -67.647059 | I16: =F16/$F$6*100 -> 2.6467757 | J16: ގެންގުޅުން
A17: Production | B17: 8 | C17: 17 | D17: 17 | E17: 13 | F17: 13 | H17: =((F17-E17)/E17*100) -> 0 | I17: =F17/$F$6*100 -> 0.62560154 | J17: އުފެއްދުން
A18: Import | B18: 7 | C18: 11 | D18: 11 | E18: 3 | F18: 9 | H18: =((F18-E18)/E18*100) -> 200 | I18: =F18/$F$6*100 -> 0.43310876 | J18: އެތެރެކުރުން
A19: Sale | B19: 4 | C19: 12 | D19: 6 | E19: 3 | F19: 13 | H19: =((F19-E19)/E19*100) -> 333.33333 | I19: =F19/$F$6*100 -> 0.62560154 | J19: ވިޔަފާރިކުރުން
A20: Others | B20: 2 | C20: 0 | D20: 34 | E20: 11 | F20: 8 | H20: =((F20-E20)/E20*100) -> -27.272727 | I20: =F20/$F$6*100 -> 0.38498556 | J20: އެހެނިހެން
A21: Other cases related to drug offences | B21: 23 | C21: 19 | D21: 19 | E21: 10 | F21: 5 | H21: =((F21-E21)/E21*100) -> -50 | I21: =F21/$F$6*100 -> 0.24061598 | J21: ޑްރަގްސް އާއި ގުޅުން ހުރި އެހެނިހެން މައްސަލަތައް
A22: Source: Maldives Police Service | J22: csivrws csilop cscviDclOm :Ivcaed utWmUluAwm
R28: =SUM(R29:R31) -> 2078 | S28: =R28/R28*100 -> 100
Q29: Drugs | R29: =F7 -> 1912 | S29: =R29/R28*100 -> 92.01155
Q30: Alcohol | R30: =F14 -> 161 | S30: =R30/R28*100 -> 7.7478345
Q31: Other cases related to drug offences | R31: =F21 -> 5 | S31: =R31/R28*100 -> 0.24061598

Sheet 8.9
A1: ތާވަލު 8.9: މޯލްޑިވްސް ޕޮލިސް ސަރވިސްގެ ފަރާތުން އަތުލައިގަތް މަސްތުވާތަކެތީގެ އަދަދު، 2009 - 2015
A2: Table 8.9: DRUG CEASED BY MALDIVES POLICE SERVICE, 2009 - 2015
A4: Type of Drug | B4: Quantity ( grams ) | E4: އަދަދު (ގްރާމްއިން) | I4: ބާވަތް
B5: 2009 | C5: 2010 | D5: 2011 | E5: 2012 | F5: 2013 | G5: 2014 | H5: 2015
A6: Total | B6: =SUM(B7:B10) -> 5627.6267 | C6: =SUM(C7:C10) -> 3737.2701 | D6: =SUM(D7:D10) -> 10180.494 | E6: =SUM(E7:E10) -> 26936.36 | F6: =SUM(F7:F10) -> 10288.645 | G6: =SUM(G7:G10) -> 26925.248 | H6: =SUM(H7:H10) -> 0 | I6: ޖުމްލަ
A7: Opiates | B7: 1350.5147 | C7: 1754.8649 | D7: 0 | E7: 0 | F7: 0 | G7: 0 | I7: އޯޕިއޭޓްސް
A8: Heroin | B8: 0 | C8: 0 | D8: 5154.4754 | E8: 10107.068 | F8: 8869.9667 | G8: 21947.937 | I8: ހެރޮއިން
A9: Cannabis | B9: 3739.5271 | C9: 1957.8159 | D9: 5026.019 | E9: 16821.554 | F9: 1418.6786 | G9: 4977.311 | I9: ކެނަބިސް
A10: Benzodyziphine | B10: 537.5849 | C10: 24.5893 | D10: 0 | E10: 7.7378 | F10: 0 | G10: 0 | I10: ބެންޒޮޑީޒިފައިން
A11: Source: Maldives Police Service | I11: މަޢުލޫމާތު ދެއްވީ: މޯލްޑިވްސް ޕޮލިސް ސަރވިސް

Sheet 8.10
A1: ތާވަލު 8.10: ހުށަހެޅިފައިވާ މާރާމާރީގެ މައްސަލަތައް، 2011- 2015
A2: Table 8.10: ASSAULT CASES LOGGED BY TYPE, 2011 - 2015
A3: Type | B3: 2011 | C3: 2012 | D3: 2013 | E3: 2014 | F3: 2015 | H3: އިންސައްތަ 2015 | I3: ކުރީ އަހަރާއި އަޅާބަލާއިރު އިތުރުވި މިންވަރު | J3: މައްސަލައިގެ ބާވަތް
H4: Percentage share | I4: %change over 2014
A5: Total | B5: =B6+B10 -> 1320 | C5: =C6+C10 -> 1264 | D5: =D6+D10 -> 1289 | E5: =E6+E10 -> 1062 | F5: =F6+F10 -> 935 | H5: =F5/F5*100 -> 100 | I5: =((F5-E5)/E5*100) -> -11.958569 | J5: ޖުމްލަ
A6: Assault by group of persons | B6: =SUM(B7:B9) -> 207 | C6: =SUM(C7:C9) -> 158 | D6: =SUM(D7:D9) -> 192 | E6: =SUM(E7:E9) -> 268 | F6: =SUM(F7:F9) -> 195 | H6: =F6/$F$5*100 -> 20.855615 | I6: =((F6-E6)/E6*100) -> -27.238806 | J6: ގްރޫޕް މާރާމާރީ
A7: Using weapons | B7: 113 | C7: 34 | D7: 23 | E7: 20 | F7: 16 | H7: =F7/$F$5*100 -> 1.7112299 | I7: =((F7-E7)/E7*100) -> -20 | J7: ހަތިޔާރު ބޭނުންކޮށްގެން
A8: Using sharp weapons | B8: 49 | C8: 38 | D8: 26 | E8: 21 | F8: 20 | H8: =F8/$F$5*100 -> 2.1390374 | I8: =((F8-E8)/E8*100) -> -4.7619048 | J8: ތޫނު ހަތިޔާރު ބޭނުންކޮށްގެން
A9: Without use of weapons | B9: 45 | C9: 86 | D9: 143 | E9: 227 | F9: 159 | H9: =F9/$F$5*100 -> 17.005348 | I9: =((F9-E9)/E9*100) -> -29.955947 | J9: ހަތިޔާރު ބޭނުންނުކޮށް
A10: Other Assault | B10: 1113 | C10: 1106 | D10: 1097 | E10: 794 | F10: 740 | H10: =F10/$F$5*100 -> 79.144385 | I10: =((F10-E10)/E10*100) -> -6.8010076 | J10: އެހެނިހެން މާރާމާރީ
A11: Source: Maldives Police Service | J11: csivrws csilop cscviDclOm :Ivcaed utWmUluAwm
N30: Assault by group of persons | O30: =F6/F5*100 -> 20.855615
N31: Other Assault | O31: =F10/F5*100 -> 79.144385

Sheet 8.11
A1: ތާވަލު 8.11: ހުށަހެޅިފައިވާ މަރުގެ މައްސަލަތައް، 2011- 2015
A2: Table 8.11 : LOGGED CASES OF DEATH , 2011 - 2015
A3: Type | B3: 2011 | C3: 2012 | D3: 2013 | E3: 2014 | F3: 2015 | G3: ކުރީ އަހަރާއި އަޅާބަލާއިރު އިތުރުވި މިންވަރު | H3: ކުރީ އަހަރާއި އަޅާބަލާއިރު އިތުރުވި މިންވަރު | I3: މައްސަލައިގެ ބާވަތް
G4: % change over 2013 | H4: % change over 2014
A5: Total | B5: =SUM(B6:B11) -> 171 | C5: =SUM(C6:C11) -> 190 | D5: =SUM(D6:D11) -> 183 | E5: 174 | F5: =SUM(F6:F11) -> 171 | G5: =((E5-D5)/D5)*100 -> -4.9180328 | H5: =((F5-E5)/E5)*100 -> -1.7241379 | I5: ޖުމްލަ
A6: Homicide | B6: 3 | C6: 10 | D6: 3 | E6: 3 | F6: 11 | G6: =((E6-D6)/D6*100) -> 0 | H6: =((F6-E6)/E6*100) -> 266.66667 | I6: ގަސްތުގައި މީހުން މެރުން
A7: Suicide | B7: 13 | C7: 8 | D7: 19 | E7: 12 | F7: 15 | G7: =((E7-D7)/D7*100) -> -36.842105 | H7: =((F7-E7)/E7*100) -> 25 | I7: އަމިއްލައަށް މަރުވުން
A8: Diving/snorkeling accidents | B8: 13 | C8: 12 | D8: 15 | E8: 14 | F8: 11 | G8: =((E8-D8)/D8*100) -> -6.6666667 | H8: =((F8-E8)/E8*100) -> -21.428571 | I8: ޑައިވިންގ / ސްނޯކްލިންގ އެކްސިޑެންޓް
A9: Traffic accidents | B9: 7 | C9: 5 | D9: 2 | E9: 10 | F9: 11 | G9: =((E9-D9)/D9*100) -> 400 | H9: =((F9-E9)/E9*100) -> 10 | I9: ޓްރެފިކް އެކްސިޑެންޓް
A10: Drowning | B10: 8 | C10: 30 | D10: 15 | E10: 13 | F10: 18 | G10: =((E10-D10)/D10*100) -> -13.333333 | H10: =((F10-E10)/E10*100) -> 38.461538 | I10: ގެނބިގެން
A11: Other death cases logged | B11: 127 | C11: 125 | D11: 129 | E11: 122 | F11: 105 | G11: =((E11-D11)/D11*100) -> -5.4263566 | H11: =((F11-E11)/E11*100) -> -13.934426 | I11: އެހެނިހެން
A12: Break down: other death cases logged
A16: Source: Maldives Police Service | I16: csivrws csilop cscviDclOm :Ivcaed utWmUluAwm

Sheet 8.12
A1: ތާވަލު 8.12: ނިންމުނު މައްސަލަތައް، 2008- 2015
A2: Table 8.12: COMPLETED CASES BY TYPE, 2008 - 2015
A3: Type of case | B3: 2008 | C3: 2009 | D3: 2010 | E3: 2011 | F3: 2012 | G3: 2013 | H3: 2014 | I3: 2015 | J3: ކުރީ އަހަރާއި އަޅާބަލާއިރު އިތުރުވި މިންވަރު | L3: އިންސައްތަ 2015 | M3: މައްސަލައިގެ ބާވަތް
J4: %change over 2014 | L4: Percenatge share 2015
A5: Total | B5: 16499 | C5: 18904 | D5: 17601 | E5: 16255 | F5: 19741 | G5: 19614 | H5: 21984 | I5: =SUM(I6:I17) -> 20290 | J5: =((I5-H5)/H5*100) -> -7.7056041 | L5: =I5/$I$5*100 -> 100 | M5: wlcmuj
A6: Theft | B6: 3846 | C6: 4479 | D6: 3956 | E6: 4608 | F6: 6289 | G6: 5734 | H6: 6785 | I6: 4618 | J6: =((I6-H6)/H6*100) -> -31.938099 | L6: =I6/$I$5*100 -> 22.75998 | M6: ވައްކަން
A7: Traffic Accidents | B7: 2544 | C7: 2723 | D7: 2560 | E7: 2135 | F7: 2167 | G7: 1962 | H7: 2267 | I7: 1998 | J7: =((I7-H7)/H7*100) -> -11.865902 | L7: =I7/$I$5*100 -> 9.8472154 | M7: ޓްރެފިކް އެކްސިޑެންޓްސް
A8: Drugs | B8: 2531 | C8: 1804 | D8: 2002 | E8: 1172 | F8: 1736 | G8: 3237 | H8: 2939 | I8: 4528 | J8: =((I8-H8)/H8*100) -> 54.066009 | L8: =I8/$I$5*100 -> 22.316412 | M8: މަސްތުވާތަކެތި
A9: Lost items | B9: 1260 | C9: 2212 | D9: 1757 | E9: 1499 | F9: 1500 | G9: 1864 | H9: 2175 | I9: 1765 | J9: =((I9-H9)/H9*100) -> -18.850575 | L9: =I9/$I$5*100 -> 8.6988664 | M9: ގެއްލޭތަކެތި
A10: Assault | B10: 1370 | C10: 1679 | D10: 1580 | E10: 1265 | F10: 1342 | G10: 1149 | H10: 1507 | I10: 1200 | J10: =((I10-H10)/H10*100) -> -20.371599 | L10: =I10/$I$5*100 -> 5.9142435 | M10: މާރާމާރީ
A11: Vandalism | B11: 433 | C11: 866 | D11: 869 | E11: 757 | F11: 849 | G11: 681 | H11: 731 | I11: 617 | J11: =((I11-H11)/H11*100) -> -15.595075 | L11: =I11/$I$5*100 -> 3.0409069 | M11: މުދަލަށް ގެއްލުންދިނުން
A12: Robbery | B12: 608 | C12: 642 | D12: 564 | E12: 661 | F12: 961 | G12: 678 | H12: 823 | I12: 590 | J12: =((I12-H12)/H12*100) -> -28.311057 | L12: =I12/$I$5*100 -> 2.9078364 | M12: ފޭރުން
A13: Sexual offences | B13: 383 | C13: 435 | D13: 581 | E13: 547 | F13: 551 | G13: 610 | H13: 619 | I13: 647 | J13: =((I13-H13)/H13*100) -> 4.5234249 | L13: =I13/$I$5*100 -> 3.1887629 | M13: ބަދުއަޙްލާޤީ
A14: Embezzelment | B14: 326 | C14: 348 | D14: 402 | E14: 317 | F14: 311 | G14: 367 | H14: 489 | I14: 759 | J14: =((I14-H14)/H14*100) -> 55.214724 | L14: =I14/$I$5*100 -> 3.740759 | M14: މަކަރާއި ޙީލަތް
A15: Domestic violence | B15: 76 | C15: 86 | D15: 125 | E15: 116 | F15: 151 | G15: 171 | H15: 245 | I15: 335 | J15: =((I15-H15)/H15*100) -> 36.734694 | L15: =I15/$I$5*100 -> 1.6510596 | M15: އާއިލީ
A16: Counterfiet | B16: 88 | C16: 133 | D16: 153 | E16: 125 | F16: 135 | G16: 106 | H16: 106 | I16: 103 | J16: =((I16-H16)/H16*100) -> -2.8301887 | L16: =I16/$I$5*100 -> 0.50763923 | M16: ވަގުފައިސާ
A17: Others | B17: 3034 | C17: 3497 | D17: 3052 | E17: 3053 | F17: 3749 | G17: 3055 | H17: 3298 | I17: 3130 | J17: =((I17-H17)/H17*100) -> -5.0939964 | L17: =I17/$I$5*100 -> 15.426318 | M17: އެހެނިހެން
A18: Source: Maldives Police Service | M18: csivrws csilop cscviDclOm :Ivcaed utWmUluAwm
AD19: Logged cases | AE19: Completed cases
AC20: Theft | AD20: ='8.1'!H6 -> 3990 | AE20: =I6 -> 4618
AC21: Traffic accidents | AD21: ='8.1'!H7 -> 2045 | AE21: =I7 -> 1998
AC22: Drugs | AD22: ='8.1'!H8 -> 2078 | AE22: =I8 -> 4528
AC23: Lost Items | AD23: ='8.1'!H9 -> 1717 | AE23: =I9 -> 1765
AC24: Assault | AD24: ='8.1'!H10 -> 935 | AE24: =I10 -> 1200
AC25: Vandalism | AD25: ='8.1'!H11 -> 534 | AE25: =I11 -> 617
AC26: Robbery | AD26: ='8.1'!H12 -> 544 | AE26: =I12 -> 590
AC27: Sexual offences | AD27: ='8.1'!H13 -> 531 | AE27: =I13 -> 647
AC28: Embezzelment | AD28: ='8.1'!H14 -> 741 | AE28: =I14 -> 759
AC29: Domestic violence | AD29: ='8.1'!H15 -> 338 | AE29: =I15 -> 335
AC30: Counterfiet and forgery | AD30: ='8.1'!H16 -> 91 | AE30: =I16 -> 103
AC31: Others | AD31: ='8.1'!H17 -> 2819 | AE31: =I17 -> 3130

Sheet 8.13
A1: 2015 - 2014 ،ތާވަލު 8.13: ހުށަހެޅިފައިވާ މައްސަލަތަކުގެ ތެރެއިން ހައްޔަރުކުރެވުނު މީހުންގެ އަދަދު އަދި ޖިންސް
A2: Table 8.13: NUMBER OF DETAINEES REPORTED BY TYPE OF OFFENCE AND SEX, 2014 - 2015
A4: Type of offence | B4: 2014 | G4: 2015 | L4: ކުށުގެ ބާވަތް
B5: Number of Logged cases | D5: Number of Detainees ހައްޔަރުކުރެވުނު މީހުންގެ އަދަދު | G5: Number of Logged cases | I5: Number of Detainees ހައްޔަރުކުރެވުނު މީހުންގެ އަދަދު
D6: Both Sexes | E6: Male | F6: Female | I6: Both Sexes | J6: Male | K6: Female
B7: ހުށަހެޅިފައިވާ މައްސަލަތަކުގެ އަދަދު | D7: ދެޖިންސް | E7: ފިރިހެން | F7: އަންހެން | G7: ހުށަހެޅިފައިވާ މައްސަލަތަކުގެ އަދަދު | I7: ދެޖިންސް | J7: ފިރިހެން | K7: އަންހެން
A8: Total | B8: =SUM(B9:B20) -> 18193 | D8: =E8+F8 -> 6983 | E8: =SUM(E9:E20) -> 6709 | F8: =SUM(F9:F20) -> 274 | G8: =SUM(G9:G20) -> 16363 | I8: =J8+K8 -> 5827 | J8: =SUM(J9:J20) -> 5547 | K8: =SUM(K9:K20) -> 280 | L8: ޖުމްލަ
A9: Assault | B9: 1062 | D9: =SUM(E9:F9) -> 556 | E9: 547 | F9: 9 | G9: 935 | I9: 577 | J9: 564 | K9: 13 | L9: މާރާމާރީ
A10: Theft | B10: 5080 | D10: =SUM(E10:F10) -> 1593 | E10: 1554 | F10: 39 | G10: 3990 | I10: 1192 | J10: 1163 | K10: 29 | L10: ވައްކަން
A11: Robbery | B11: 620 | D11: =SUM(E11:F11) -> 243 | E11: 232 | F11: 11 | G11: 544 | I11: 143 | J11: 132 | K11: 11 | L11: ފޭރުން
A12: Drugs | B12: 3140 | D12: =SUM(E12:F12) -> 3316 | E12: 3158 | F12: 158 | G12: 2078 | I12: 2349 | J12: 2234 | K12: 115 | L12: މަސްތުވާތަކެތި
A13: Sexual Offences | B13: 475 | D13: =SUM(E13:F13) -> 310 | E13: 280 | F13: 30 | G13: 531 | I13: 325 | J13: 290 | K13: 35 | L13: ޖިންސީ މައްސަލަ
A14: Traffic accidents | B14: 2137 | D14: =SUM(E14:F14) -> 11 | E14: 11 | F14: 0 | G14: 2045 | I14: 9 | J14: 9 | K14: 0 | L14: ޓްރެފިކް
A15: Domestic violence | B15: 186 | D15: =SUM(E15:F15) -> 38 | E15: 36 | F15: 2 | G15: 338 | I15: 55 | J15: 43 | K15: 12 | L15: އާއިލީ
A16: Counterfeit and forgery | B16: 77 | D16: =SUM(E16:F16) -> 10 | E16: 9 | F16: 1 | G16: 91 | I16: 12 | J16: 12 | K16: 0 | L16: ވަގުފައިސާ
A17: Vandalism | B17: 520 | D17: =SUM(E17:F17) -> 147 | E17: 147 | F17: 0 | G17: 534 | I17: 126 | J17: 121 | K17: 5 | L17: މުދަލަށް ގެއްލުންދިނުން
A18: Embezzlement | B18: 377 | D18: =SUM(E18:F18) -> 80 | E18: 78 | F18: 2 | G18: 741 | I18: 63 | J18: 60 | K18: 3 | L18: މަކަރާއި ޙީލަތް
A19: Lost items | B19: 2014 | D19: =SUM(E19:F19) -> 2 | E19: 2 | F19: 0 | G19: 1717 | I19: 2 | J19: 1 | K19: 1 | L19: ގެއްލޭތަކެތި
A20: Others | B20: 2505 | D20: =SUM(E20:F20) -> 677 | E20: 655 | F20: 22 | G20: 2819 | I20: 974 | J20: 918 | K20: 56 | L20: އެހެނިހެން
A21: Source: Maldives Police Service | L21: csivrws csilop cscviDclOm :Ivcaed utWmUluAwm
V32: Male | W32: Female
U33: Assault | V33: =J9/I9*100 -> 97.746967 | W33: =K9/I9*100 -> 2.2530329
U34: Theft | V34: =J10/I10*100 -> 97.567114 | W34: =K10/I10*100 -> 2.4328859
U35: Robbery | V35: =J11/I11*100 -> 92.307692 | W35: =K11/I11*100 -> 7.6923077
U36: Drugs | V36: =J12/I12*100 -> 95.1043 | W36: =K12/I12*100 -> 4.8957003
U37: Sexual Offences | V37: =J13/I13*100 -> 89.230769 | W37: =K13/I13*100 -> 10.769231
U38: Traffic accidents | V38: =J14/I14*100 -> 100 | W38: =K14/I14*100 -> 0
U39: Domestic violence | V39: =J15/I15*100 -> 78.181818 | W39: =K15/I15*100 -> 21.818182
U40: Counterfeit and forgery | V40: =J16/I16*100 -> 100 | W40: =K16/I16*100 -> 0
U41: Vandalism | V41: =J17/I17*100 -> 96.031746 | W41: =K17/I17*100 -> 3.968254
U42: Embezzlement | V42: =J18/I18*100 -> 95.238095 | W42: =K18/I18*100 -> 4.7619048
U43: Lost items | V43: =J19/I19*100 -> 50 | W43: =K19/I19*100 -> 50
U44: Others | V44: =J20/I20*100 -> 94.250513 | W44: =K20/I20*100 -> 5.7494867

Sheet 8.14
A2: 2015 - 2009 ތާވަލު 8.14: އެކިއެކި މައްސަލަތަކުގައި ހައްޔަރުކުރެވުނު މީހުންގެ ތެރޭން ތަކުރާރުކޮށް ހައްޔަރުކުރެވުނު މީހުންގެ އަދަދު،
A3: Table 8.14: NUMBER OF DETAINEES BY NUMBER OF TIMES ARRESTED, 2009 - 2015
A4: No. of times arrested | B4: 2009 | C4: 2010 | D4: 2011 | E4: 2012 | F4: 2013 | G4: 2014 | H4: 2015 | I4: ހައްޔަރު ކުރެވުނު އަދަދު
A5: Total | B5: =SUM(B6:B15) -> 5081 | C5: =SUM(C6:C15) -> 4140 | D5: =SUM(D6:D15) -> 5279 | E5: =SUM(E6:E15) -> 6339 | F5: =SUM(F6:F18) -> 6981 | G5: =SUM(G6:G18) -> 6983 | H5: =SUM(H6:H18) -> 5827 | I5: ޖުމްލަ
A6: 1 | B6: 3700 | C6: 3347 | D6: 4086 | E6: 4710 | F6: 4666 | G6: 4443 | H6: 4118 | I6: 1
A7: 2 | B7: 840 | C7: 569 | D7: 810 | E7: 1031 | F7: 1255 | G7: 1274 | H7: 1002 | I7: 2
A8: 3 | B8: 326 | C8: 158 | D8: 263 | E8: 367 | F8: 543 | G8: 594 | H8: 362 | I8: 3
A9: 4 | B9: 141 | C9: 47 | D9: 84 | E9: 148 | F9: 258 | G9: 308 | H9: 157 | I9: 4
A10: 5 | B10: 51 | C10: 13 | D10: 26 | E10: 59 | F10: 124 | G10: 168 | H10: 81 | I10: 5
A11: 6 | B11: 14 | C11: 5 | D11: 7 | E11: 17 | F11: 68 | G11: 85 | H11: 47 | I11: 6
A12: 7 | B12: 6 | C12: 1 | D12: 2 | E12: 4 | F12: 33 | G12: 52 | H12: 26 | I12: 7
A13: 8 | B13: 2 | C13: 0 | D13: 1 | E13: 1 | F13: 15 | G13: 27 | H13: 13 | I13: 8
A14: 9 | B14: 1 | C14: 0 | D14: 0 | E14: 1 | F14: 9 | G14: 18 | H14: 12 | I14: 9
A15: 10 | B15: 0 | C15: 0 | D15: 0 | E15: 1 | F15: 6 | G15: 8 | H15: 5 | I15: 10
A16: 11 | B16: 0 | C16: 0 | D16: 0 | E16: 0 | F16: 2 | G16: 4 | H16: 3 | I16: 11
A17: 12 | B17: 0 | C17: 0 | D17: 0 | E17: 0 | F17: 1 | G17: 2 | H17: 1 | I17: 12
A18: 13 | B18: 0 | C18: 0 | D18: 0 | E18: 0 | F18: 1 | G18: 0 | H18: 0 | I18: 13
A19: Source: Maldives Police Service | I19: މަޢުލޫމާތު ދެއްވީ: މޯލްޑިވްސް ޕޮލިސް ސަރވިސް
R28: 1 | S28: 4118
R29: 2 | S29: 1002
R30: 3 | S30: 362
R31: 4 | S31: 157
R32: 5 | S32: 81
R33: more than 6 | S33: 107

Sheet 8.15
A2: ތާވަލު 8.15: ހުށަހެޅިފައިވާ މައްސަލަތަކުގެ ތެރެއިން ހައްޔަރުކުރެވުނު މީހުންގެ އަދަދު ޖިންސް އަދި އުމުރުފުރާއިން، 2015
A3: Table 8.15: NUMBER OF DETAINEES REPORTED BY TYPE OF OFFENCES, GENDER AND AGE GROUP, 2015
A5: Type of offence | B5: Both sexes | G5: Male | L5: Female | P5: ކުށުގެ ބާވަތް
B6: ދެޖިންސް | G6: ފިރިހެން | L6: އަންހެން
B7: Total | C7: < 18 | D7: 18 - 34 | E7: 35 + | G7: Total | H7: < 18 | I7: 18 - 34 | J7: 35 + | L7: Total | M7: < 18 | N7: 18 - 34 | O7: 35 +
B8: ޖުމްލަ | C8: 18 އަހަރުންދަށް | D8: 18-34 އަހަރާއި ދެމެދު | E8: 35 އަހަރުން މަތި | G8: ޖުމްލަ | H8: 18 އަހަރުންދަށް | I8: 18-34 އަހަރާއި ދެމެދު | J8: 35 އަހަރުން މަތި | L8: ޖުމްލަ | M8: 18 އަހަރުންދަށް | N8: 18-34 އަހަރާއި ދެމެދު | O8: 35 އަހަރުން މަތި
A9: Total | B9: =G9+L9 -> 5827 | C9: =H9+M9 -> 278 | D9: =I9+N9 -> 4365 | E9: =J9+O9 -> 1184 | G9: =SUM(H9:J9) -> 5547 | H9: =SUM(H10:H21) -> 255 | I9: =SUM(I10:I21) -> 4159 | J9: =SUM(J10:J21) -> 1133 | L9: =SUM(M9:O9) -> 280 | M9: =SUM(M10:M21) -> 23 | N9: =SUM(N10:N21) -> 206 | O9: =SUM(O10:O21) -> 51 | P9: ޖުމްލަ
A10: Assault | B10: =G10+L10 -> 577 | C10: =H10+M10 -> 41 | D10: =I10+N10 -> 464 | E10: =J10+O10 -> 72 | G10: =SUM(H10:J10) -> 564 | H10: 40 | I10: 453 | J10: 71 | L10: =SUM(M10:O10) -> 13 | M10: 1 | N10: 11 | O10: 1 | P10: މާރާމާރީ
A11: Theft | B11: =G11+L11 -> 1192 | C11: =H11+M11 -> 44 | D11: =I11+N11 -> 935 | E11: =J11+O11 -> 213 | G11: =SUM(H11:J11) -> 1163 | H11: 44 | I11: 913 | J11: 206 | L11: =SUM(M11:O11) -> 29 | M11: 0 | N11: 22 | O11: 7 | P11: ވައްކަން
A12: Robbery | B12: =G12+L12 -> 143 | C12: =H12+M12 -> 8 | D12: =I12+N12 -> 120 | E12: =J12+O12 -> 15 | G12: =SUM(H12:J12) -> 132 | H12: 8 | I12: 110 | J12: 14 | L12: =SUM(M12:O12) -> 11 | M12: 0 | N12: 10 | O12: 1 | P12: ފޭރުން | Z12: < 18 yrs | AA12: 18 - 34 yrs | AB12: 35 yrs and above
A13: Drugs | B13: =G13+L13 -> 2349 | C13: =H13+M13 -> 118 | D13: =I13+N13 -> 1773 | E13: =J13+O13 -> 458 | G13: =SUM(H13:J13) -> 2234 | H13: 107 | I13: 1686 | J13: 441 | L13: =SUM(M13:O13) -> 115 | M13: 11 | N13: 87 | O13: 17 | P13: މަސްތުވާތަކެތި | Z13: =C9 -> 278 | AA13: =D9 -> 4365 | AB13: =E9 -> 1184
A14: Sexual Offences | B14: =G14+L14 -> 325 | C14: =H14+M14 -> 14 | D14: =I14+N14 -> 196 | E14: =J14+O14 -> 115 | G14: =SUM(H14:J14) -> 290 | H14: 11 | I14: 170 | J14: 109 | L14: =SUM(M14:O14) -> 35 | M14: 3 | N14: 26 | O14: 6 | P14: ޖިންސީ މައްސަލަ
A15: Traffic | B15: =G15+L15 -> 9 | C15: =H15+M15 -> 4 | D15: =I15+N15 -> 4 | E15: =J15+O15 -> 1 | G15: =SUM(H15:J15) -> 9 | H15: 4 | I15: 4 | J15: 1 | L15: =SUM(M15:O15) -> 0 | M15: 0 | N15: 0 | O15: 0 | P15: ޓްރެފިކް | AA15: =SUM(AA16:AA17) -> 5827
A16: Domestic violence | B16: =G16+L16 -> 55 | C16: =H16+M16 -> 5 | D16: =I16+N16 -> 34 | E16: =J16+O16 -> 16 | G16: =SUM(H16:J16) -> 43 | H16: 5 | I16: 24 | J16: 14 | L16: =SUM(M16:O16) -> 12 | M16: 0 | N16: 10 | O16: 2 | P16: އާއިލީ | Z16: Male | AA16: =G9 -> 5547 | AB16: =AA16/AA15*100 -> 95.194783
A17: Counterfeit and forgery | B17: =G17+L17 -> 12 | C17: =H17+M17 -> 0 | D17: =I17+N17 -> 9 | E17: =J17+O17 -> 3 | G17: =SUM(H17:J17) -> 12 | H17: 0 | I17: 9 | J17: 3 | L17: =SUM(M17:O17) -> 0 | M17: 0 | N17: 0 | O17: 0 | P17: ވަގުފައިސާ | Z17: Female | AA17: =L9 -> 280 | AB17: =AA17/AA16*100 -> 5.0477736
A18: Vandalism | B18: =G18+L18 -> 126 | C18: =H18+M18 -> 18 | D18: =I18+N18 -> 92 | E18: =J18+O18 -> 16 | G18: =SUM(H18:J18) -> 121 | H18: 14 | I18: 91 | J18: 16 | L18: =SUM(M18:O18) -> 5 | M18: 4 | N18: 1 | O18: 0 | P18: މުދަލަށް ގެއްލުންދިނުން
A19: Embezzlement | B19: =G19+L19 -> 63 | C19: =H19+M19 -> 0 | D19: =I19+N19 -> 42 | E19: =J19+O19 -> 21 | G19: =SUM(H19:J19) -> 60 | H19: 0 | I19: 40 | J19: 20 | L19: =SUM(M19:O19) -> 3 | M19: 0 | N19: 2 | O19: 1 | P19: މަކަރާއި ޙީލަތް
A20: Lost items | B20: =G20+L20 -> 2 | C20: =H20+M20 -> 0 | D20: =I20+N20 -> 2 | E20: =J20+O20 -> 0 | G20: =SUM(H20:J20) -> 1 | H20: 0 | I20: 1 | J20: 0 | L20: =SUM(M20:O20) -> 1 | M20: 0 | N20: 1 | O20: 0 | P20: ގެއްލޭތަކެތި
A21: Others | B21: =G21+L21 -> 974 | C21: =H21+M21 -> 26 | D21: =I21+N21 -> 694 | E21: =J21+O21 -> 254 | G21: =SUM(H21:J21) -> 918 | H21: 22 | I21: 658 | J21: 238 | L21: =SUM(M21:O21) -> 56 | M21: 4 | N21: 36 | O21: 16 | P21: އެހެނިހެން | AA21: Male | AB21: Female
A22: Source: Maldives Police Service | P22: މަޢުލޫމާތު ދެއްވީ: މޯލްޑިވްސް ޕޮލިސް ސަރވިސް | Z22: < 18 yrs | AA22: =H9 -> 255 | AB22: =M9 -> 23
Z23: 18 - 34 yrs | AA23: =I9 -> 4159 | AB23: =N9 -> 206
Z24: 35 yrs and above | AA24: =J9 -> 1133 | AB24: =O9 -> 51

Sheet 8.16
A1: ތާވަލް 8.16: ހައްޔަރު ކުރެވުނު ދިވެހިންނާއި ބިދޭސީންގެ އަދަދު، 2011 - 2015
A2: Table: 8.16 NUMBER OF LOCAL AND FOREIGN DETAINEES BY TYPE OF OFFENCES, 2011 - 2015
A4: Type of Offence | B4: ޖުމްލަ | C4: ދިވެހިން | D4: ބިދޭސީ | E4: ޖުމްލަ | F4: ދިވެހިން | G4: ބިދޭސީ | H4: ޖުމްލަ | I4: ދިވެހިން | J4: ބިދޭސީ | K4: ޖުމްލަ | L4: ދިވެހިން | M4: ބިދޭސީ | N4: ޖުމްލަ | O4: ދިވެހިން | P4: ބިދޭސީ | Q4: ޖުމްލަ | R4: ދިވެހިން | S4: ބިދޭސީ | T4: ކުށުގެ ބާވަތް
B5: Total | C5: Locals | D5: Foreign | E5: Total | F5: Locals | G5: Foreign | H5: Total | I5: Locals | J5: Foreign | K5: Total | L5: Locals | M5: Foreign | N5: Total | O5: Locals | P5: Foreign | Q5: Total | R5: Locals | S5: Foreign
B6: 2010 | E6: 2011 | H6: 2012 | K6: 2013 | N6: 2014 | Q6: 2015 | W6: Locals | X6: Foreigners
A7: Total | B7: 4141 | C7: 3533 | D7: =SUM(D8:D19) -> 608 | E7: =SUM(E8:E19) -> 5279 | F7: =SUM(F8:F19) -> 4554 | G7: =SUM(G8:G19) -> 725 | H7: =I7+J7 -> 6339 | I7: =SUM(I8:I19) -> 5734 | J7: =SUM(J8:J19) -> 605 | K7: =L7+M7 -> 6981 | L7: =SUM(L8:L19) -> 6422 | M7: =SUM(M8:M19) -> 559 | N7: =O7+P7 -> 6983 | O7: =SUM(O8:O19) -> 6555 | P7: =SUM(P8:P19) -> 428 | Q7: =R7+S7 -> 5827 | R7: =SUM(R8:R19) -> 5446 | S7: =SUM(S8:S19) -> 381 | T7: ޖުމްލަ | W7: =R7/Q7*100 -> 93.461472 | X7: =S7/Q7*100 -> 6.5385275
A8: Assault | B8: 945 | C8: 857 | D8: 88 | E8: 967 | F8: 884 | G8: 83 | H8: =I8+J8 -> 677 | I8: 624 | J8: 53 | K8: =L8+M8 -> 668 | L8: 620 | M8: 48 | N8: =O8+P8 -> 556 | O8: 514 | P8: 42 | Q8: =R8+S8 -> 577 | R8: 538 | S8: 39 | T8: މާރާމާރީ
A9: Theft | B9: 774 | C9: 663 | D9: 111 | E9: 1149 | F9: 1034 | G9: 115 | H9: =I9+J9 -> 1474 | I9: 1379 | J9: 95 | K9: =L9+M9 -> 1613 | L9: 1523 | M9: 90 | N9: =O9+P9 -> 1593 | O9: 1501 | P9: 92 | Q9: =R9+S9 -> 1192 | R9: 1126 | S9: 66 | T9: ވައްކަން
A10: Robbery | B10: 199 | C10: 186 | D10: 13 | E10: 292 | F10: 263 | G10: 29 | H10: =I10+J10 -> 277 | I10: 272 | J10: 5 | K10: =L10+M10 -> 268 | L10: 258 | M10: 10 | N10: =O10+P10 -> 243 | O10: 240 | P10: 3 | Q10: =R10+S10 -> 143 | R10: 141 | S10: 2 | T10: ފޭރުން
A11: Drugs | B11: 1160 | C11: 1104 | D11: 56 | E11: 1453 | F11: 1394 | G11: 59 | H11: =I11+J11 -> 2073 | I11: 1969 | J11: 104 | K11: =L11+M11 -> 2906 | L11: 2799 | M11: 107 | N11: =O11+P11 -> 3316 | O11: 3209 | P11: 107 | Q11: =R11+S11 -> 2349 | R11: 2262 | S11: 87 | T11: މަސްތުވާތަކެތި
A12: Sexual Offences | B12: 299 | C12: 221 | D12: 78 | E12: 447 | F12: 328 | G12: 119 | H12: =I12+J12 -> 423 | I12: 290 | J12: 133 | K12: =L12+M12 -> 404 | L12: 302 | M12: 102 | N12: =O12+P12 -> 310 | O12: 235 | P12: 75 | Q12: =R12+S12 -> 325 | R12: 258 | S12: 67 | T12: ޖިންސީ މައްސަލަ
A13: Traffic | B13: 9 | C13: 9 | D13: 0 | E13: 9 | F13: 8 | G13: 1 | H13: =I13+J13 -> 12 | I13: 12 | J13: 0 | K13: =L13+M13 -> 6 | L13: 6 | M13: 0 | N13: =O13+P13 -> 11 | O13: 11 | P13: 0 | Q13: =R13+S13 -> 9 | R13: 9 | S13: 0 | T13: ޓްރެފިކް
A14: Domestic violence | B14: 11 | C14: 11 | D14: 0 | E14: 34 | F14: 30 | G14: 4 | H14: =I14+J14 -> 36 | I14: 35 | J14: 1 | K14: =L14+M14 -> 33 | L14: 33 | M14: 0 | N14: =O14+P14 -> 38 | O14: 37 | P14: 1 | Q14: =R14+S14 -> 55 | R14: 52 | S14: 3 | T14: އާއިލީ
A15: Counterfeit and forgery | B15: 31 | C15: 19 | D15: 12 | E15: 52 | F15: 25 | G15: 27 | H15: =I15+J15 -> 24 | I15: 16 | J15: 8 | K15: =L15+M15 -> 30 | L15: 23 | M15: 7 | N15: =O15+P15 -> 10 | O15: 9 | P15: 1 | Q15: =R15+S15 -> 12 | R15: 8 | S15: 4 | T15: ވަގުފައިސާ
A16: Vandalism | B16: 79 | C16: 78 | D16: 1 | E16: 106 | F16: 104 | G16: 2 | H16: =I16+J16 -> 149 | I16: 135 | J16: 14 | K16: =L16+M16 -> 122 | L16: 121 | M16: 1 | N16: =O16+P16 -> 147 | O16: 145 | P16: 2 | Q16: =R16+S16 -> 126 | R16: 123 | S16: 3 | T16: މުދަލަށް ގެއްލުންދިނުން
A17: Embezzlement | B17: 52 | C17: 29 | D17: 23 | E17: 60 | F17: 39 | G17: 21 | H17: =I17+J17 -> 40 | I17: 29 | J17: 11 | K17: =L17+M17 -> 59 | L17: 51 | M17: 8 | N17: =O17+P17 -> 80 | O17: 60 | P17: 20 | Q17: =R17+S17 -> 63 | R17: 44 | S17: 19 | T17: މަކަރާއި ޙީލަތް
A18: Lost items | B18: 12 | C18: 10 | D18: 2 | E18: 7 | F18: 5 | G18: 2 | H18: =I18+J18 -> 7 | I18: 4 | J18: 3 | K18: =L18+M18 -> 3 | L18: 3 | M18: 0 | N18: =O18+P18 -> 2 | O18: 2 | P18: 0 | Q18: =R18+S18 -> 2 | R18: 2 | S18: 0 | T18: ގެއްލޭތަކެތި
A19: Others | B19: 570 | C19: 346 | D19: 224 | E19: 703 | F19: 440 | G19: 263 | H19: =I19+J19 -> 1147 | I19: 969 | J19: 178 | K19: =L19+M19 -> 869 | L19: 683 | M19: 186 | N19: =O19+P19 -> 677 | O19: 592 | P19: 85 | Q19: =R19+S19 -> 974 | R19: 883 | S19: 91 | T19: އެހެނިހެން
A20: Source: Maldives Police Service | T20: މަޢުލޫމާތު ދެއްވީ: މޯލްޑިވްސް ޕޮލިސް ސަރވިސް

Sheet 8.17
A1: ތާވަލު 8.17: ފުލުހުންގެ ޚިދުމަތުގައި ތިބީ މީހުންގެ އަދަދު އަދި ހިނގި ޚަރަދު، 2010 - 2015
A2: TABLE 8.17: POLICE PERSONNEL BY SEX AND FINANCIAL RESOURCES, 2010 - 2015
A4: Details | B4: Year އަހަރު | H4: ތަފްސީލް
B5: 2010 | C5: 2011 | D5: 2012 | E5: 2013 | F5: 2014 | G5: 2015
A6: Total police personnel | B6: =SUM(B7:B8) -> 2933 | C6: =SUM(C7:C8) -> 2975 | D6: =SUM(D7:D8) -> 3217 | E6: =SUM(E7:E8) -> 3003 | F6: =SUM(F7:F8) -> 3214 | G6: =SUM(G7:G8) -> 3820 | H6: ޖުމްލަ ފުލުހުންގެ އަދަދު
A7: Male | B7: 2640 | C7: 2690 | D7: 2923 | E7: 2732 | F7: 2938 | G7: 3360 | H7: ފިރިހެން
A8: Female | B8: 293 | C8: 285 | D8: 294 | E8: 271 | F8: 276 | G8: 460 | H8: އަންހެން
A9: Total police expenditure (million MVR) | B9: 714.5059 | C9: 743.81639 | D9: 837.16104 | E9: 902.77046 | F9: 1049.5819 | G9: 1062.91 | H9: ފުލުހުންނަށް ހިނގި ޚަރަދު (މިލިއަން ރުފިޔާ)
A10: Source: Maldives Police Service | H10: މަޢުލޫމާތު ދެއްވީ: މޯލްޑިވްސް ޕޮލިސް ސަރވިސް

Sheet 8.20 workings
A1: ތާވަލު 8.9: ހުށަހެޅުނު، ނިމުނު އަދި ނުނިމެ ހުރި މައްސަލަތައް، 2012
A2: Table 8.9: CASES FILED, CONCLUDED AND PENDING BY CASE TYPE, 2012
C3: Criminal Cases | J3: Criminal Cases above 18 | P3: Criminal Cases below 18 | X3: Civil Cases | AE3: Family Cases
C4: Starting Balance | D4: New cases filed | E4: Total | F4: Concluded | G4: Ending Balance | H4: % share completed | I4: % share pending | J4: Starting Balance | K4: New cases filed | L4: Total | M4: Concluded | N4: Ending Balance | O4: % share completed | P4: Starting Balance | Q4: New cases filed | R4: Total | S4: Concluded | T4: Ending Balance | U4: % share completed | X4: Starting Balance | Y4: New cases filed | Z4: Total | AA4: Concluded | AB4: Ending Balance | AC4: % share completed | AE4: Starting Balance | AF4: New cases filed | AG4: Total | AH4: Concluded | AI4: Ending Balance | AJ4: % share completed
B5: Republic | C5: =J5+P5 -> 3010 | D5: =K5+Q5 -> 2381 | E5: =L5+R5 -> 5391 | F5: =M5+S5 -> 1774 | G5: =N5+T5 -> 3617 | H5: =F5/E5*100 -> 32.906696 | I5: =G5/E5*100 -> 67.093304 | J5: 2893 | K5: 2200 | L5: 5093 | M5: 1617 | N5: 3476 | O5: =M5/L5*100 -> 31.74946 | P5: 117 | Q5: 181 | R5: 298 | S5: 157 | T5: 141 | U5: =S5/R5*100 -> 52.684564 | W5: Republic | X5: 3628 | Y5: 6873 | Z5: 10500 | AA5: 6554 | AB5: 3946 | AC5: =AA5/Z5*100 -> 62.419048 | AD5: Republic | AE5: 890 | AF5: 6097 | AG5: 6987 | AH5: 5904 | AI5: 1083 | AJ5: =AH5/AG5*100 -> 84.499785
B6: Male' | C6: =J6+P6 -> 2247 | D6: =K6+Q6 -> 1246 | E6: =L6+R6 -> 3493 | F6: =M6+S6 -> 1084 | G6: =N6+T6 -> 2409 | H6: =F6/E6*100 -> 31.033496 | I6: =G6/E6*100 -> 68.966504 | J6: 2193 | K6: 1163 | L6: 3356 | M6: 990 | N6: 2366 | O6: =M6/L6*100 -> 29.499404 | P6: 54 | Q6: 83 | R6: 137 | S6: 94 | T6: 43 | U6: =S6/R6*100 -> 68.613139 | W6: Male' | X6: 1847 | Y6: 2725 | Z6: 4571 | AA6: 2719 | AB6: 1852 | AC6: =AA6/Z6*100 -> 59.483702 | AD6: Male' | AE6: 456 | AF6: 2367 | AG6: 2823 | AH6: 2296 | AI6: 527 | AJ6: =AH6/AG6*100 -> 81.331916
B7: Atoll | C7: =J7+P7 -> 763 | D7: =K7+Q7 -> 1135 | E7: =L7+R7 -> 1898 | F7: =M7+S7 -> 690 | G7: =N7+T7 -> 1208 | H7: =F7/E7*100 -> 36.354057 | I7: =G7/E7*100 -> 63.645943 | J7: 700 | K7: 1037 | L7: 1737 | M7: 627 | N7: 1110 | O7: =M7/L7*100 -> 36.096718 | P7: 63 | Q7: 98 | R7: 161 | S7: 63 | T7: 98 | U7: =S7/R7*100 -> 39.130435 | W7: Atoll | X7: 1781 | Y7: 4148 | Z7: 5929 | AA7: 3835 | AB7: 2094 | AC7: =AA7/Z7*100 -> 64.682071 | AD7: Atoll | AE7: 434 | AF7: 3730 | AG7: 4164 | AH7: 3608 | AI7: 556 | AJ7: =AH7/AG7*100 -> 86.647454
A8: HA | B8: Total | C8: =J8+P8 -> 68 | D8: =K8+Q8 -> 28 | E8: =L8+R8 -> 96 | F8: =M8+S8 -> 21 | G8: =N8+T8 -> 75 | J8: 61 | K8: 27 | L8: 88 | M8: 18 | N8: 70 | P8: 7 | Q8: 1 | R8: 8 | S8: 3 | T8: 5 | X8: 123 | Y8: 181 | Z8: 304 | AA8: 148 | AB8: 156 | AE8: 21 | AF8: 169 | AG8: 190 | AH8: 170 | AI8: 20
A9: HDh | B9: Total | C9: =J9+P9 -> 81 | D9: =K9+Q9 -> 73 | E9: =L9+R9 -> 154 | F9: =M9+S9 -> 41 | G9: =N9+T9 -> 113 | J9: 74 | K9: 69 | L9: 143 | M9: 34 | N9: 109 | P9: 7 | Q9: 4 | R9: 11 | S9: 7 | T9: 4 | X9: 93 | Y9: 178 | Z9: 271 | AA9: 104 | AB9: 167 | AE9: 34 | AF9: 233 | AG9: 267 | AH9: 222 | AI9: 45
A10: Sh | B10: Total | C10: =J10+P10 -> 10 | D10: =K10+Q10 -> 24 | E10: =L10+R10 -> 34 | F10: =M10+S10 -> 28 | G10: =N10+T10 -> 6 | J10: 10 | K10: 22 | L10: 32 | M10: 28 | N10: 4 | P10: 0 | Q10: 2 | R10: 2 | S10: 0 | T10: 2 | X10: 43 | Y10: 145 | Z10: 188 | AA10: 142 | AB10: 46 | AE10: 16 | AF10: 162 | AG10: 178 | AH10: 162 | AI10: 16
A11: N | B11: Total | C11: =J11+P11 -> 48 | D11: =K11+Q11 -> 62 | E11: =L11+R11 -> 110 | F11: =M11+S11 -> 45 | G11: =N11+T11 -> 65 | J11: 47 | K11: 58 | L11: 105 | M11: 42 | N11: 63 | P11: 1 | Q11: 4 | R11: 5 | S11: 3 | T11: 2 | X11: 117 | Y11: 186 | Z11: 303 | AA11: 174 | AB11: 129 | AE11: 30 | AF11: 215 | AG11: 245 | AH11: 188 | AI11: 57
A12: R | B12: Total | C12: =J12+P12 -> 73 | D12: =K12+Q12 -> 84 | E12: =L12+R12 -> 157 | F12: =M12+S12 -> 80 | G12: =N12+T12 -> 77 | J12: 70 | K12: 78 | L12: 148 | M12: 76 | N12: 72 | P12: 3 | Q12: 6 | R12: 9 | S12: 4 | T12: 5 | X12: 71 | Y12: 202 | Z12: 273 | AA12: 186 | AB12: 87 | AE12: 18 | AF12: 231 | AG12: 249 | AH12: 219 | AI12: 30
A13: B | B13: Total | C13: =J13+P13 -> 21 | D13: =K13+Q13 -> 26 | E13: =L13+R13 -> 47 | F13: =M13+S13 -> 10 | G13: =N13+T13 -> 37 | J13: 17 | K13: 23 | L13: 40 | M13: 9 | N13: 31 | P13: 4 | Q13: 3 | R13: 7 | S13: 1 | T13: 6 | X13: 38 | Y13: 183 | Z13: 221 | AA13: 119 | AB13: 102 | AE13: 20 | AF13: 135 | AG13: 155 | AH13: 124 | AI13: 31
A14: Lh | B14: Total | C14: =J14+P14 -> 77 | D14: =K14+Q14 -> 61 | E14: =L14+R14 -> 138 | F14: =M14+S14 -> 57 | G14: =N14+T14 -> 81 | J14: 72 | K14: 57 | L14: 129 | M14: 52 | N14: 77 | P14: 5 | Q14: 4 | R14: 9 | S14: 5 | T14: 4 | X14: 124 | Y14: 124 | Z14: 248 | AA14: 127 | AB14: 121 | AE14: 44 | AF14: 178 | AG14: 222 | AH14: 182 | AI14: 40
A15: K | B15: Total | C15: =J15+P15 -> 31 | D15: =K15+Q15 -> 41 | E15: =L15+R15 -> 72 | F15: =M15+S15 -> 31 | G15: =N15+T15 -> 41 | J15: 30 | K15: 37 | L15: 67 | M15: 30 | N15: 37 | P15: 1 | Q15: 4 | R15: 5 | S15: 1 | T15: 4 | X15: 67 | Y15: 145 | Z15: 212 | AA15: 153 | AB15: 59 | AE15: 17 | AF15: 218 | AG15: 235 | AH15: 217 | AI15: 18
A16: AA | B16: Total | C16: =J16+P16 -> 13 | D16: =K16+Q16 -> 13 | E16: =L16+R16 -> 26 | F16: =M16+S16 -> 11 | G16: =N16+T16 -> 15 | J16: 12 | K16: 11 | L16: 23 | M16: 11 | N16: 12 | P16: 1 | Q16: 2 | R16: 3 | S16: 0 | T16: 3 | X16: 58 | Y16: 123 | Z16: 181 | AA16: 142 | AB16: 39 | AE16: 9 | AF16: 123 | AG16: 132 | AH16: 126 | AI16: 6
A17: ADh | B17: Total | C17: =J17+P17 -> 14 | D17: =K17+Q17 -> 18 | E17: =L17+R17 -> 32 | F17: =M17+S17 -> 23 | G17: =N17+T17 -> 9 | J17: 13 | K17: 16 | L17: 29 | M17: 22 | N17: 7 | P17: 1 | Q17: 2 | R17: 3 | S17: 1 | T17: 2 | X17: 78 | Y17: 145 | Z17: 223 | AA17: 155 | AB17: 68 | AE17: 25 | AF17: 141 | AG17: 166 | AH17: 138 | AI17: 28
A18: V | B18: Total | C18: =J18+P18 -> 2 | D18: =K18+Q18 -> 1 | E18: =L18+R18 -> 3 | F18: =M18+S18 -> 2 | G18: =N18+T18 -> 1 | J18: 2 | K18: 1 | L18: 3 | M18: 2 | N18: 1 | P18: 0 | Q18: 0 | R18: 0 | S18: 0 | T18: 0 | X18: 6 | Y18: 33 | Z18: 39 | AA18: 28 | AB18: 11 | AE18: 2 | AF18: 19 | AG18: 21 | AH18: 21 | AI18: 0
A19: M | B19: Total | C19: =J19+P19 -> 4 | D19: =K19+Q19 -> 4 | E19: =L19+R19 -> 8 | F19: =M19+S19 -> 3 | G19: =N19+T19 -> 5 | J19: 4 | K19: 3 | L19: 7 | M19: 3 | N19: 4 | P19: 0 | Q19: 1 | R19: 1 | S19: 0 | T19: 1 | X19: 89 | Y19: 62 | Z19: 151 | AA19: 109 | AB19: 42 | AE19: 6 | AF19: 72 | AG19: 78 | AH19: 71 | AI19: 7
... A32: Male' | B32: HulhuMale' Court | C32: =J32+P32 -> 2 | D32: =K32+Q32 -> 5 | E32: =L32+R32 -> 7 | F32: =M32+S32 -> 0 | G32: =N32+T32 -> 7 | J32: 2 | K32: 5 | L32: 7 | M32: 0 | N32: 7 | P32: 0 | Q32: 0 | R32: 0 | S32: 0 | T32: 0 | X32: 111 | Y32: 448 | Z32: 558 | AA32: 307 | AB32: 251 | AE32: 5 | AF32: 116 | AG32: 121 | AH32: 102 | AI32: 19
A33: Source: Department of Judicial Administration | AI33: cnwxErcTcsinimcDea clwxiDuj cfoa cTcnwmcTWpiD : utWmUluAwm
B36: % share completed
B37: Criminal Cases | C37: Civil cases | D37: Family Cases
A38: Republic | B38: =H5 -> 32.906696 | C38: =AC5 -> 62.419048 | D38: =AJ5 -> 84.499785
A39: Male' | B39: =H6 -> 31.033496 | C39: =AC6 -> 59.483702 | D39: =AJ6 -> 81.331916
A40: Atoll | B40: =H7 -> 36.354057 | C40: =AC7 -> 64.682071 | D40: =AJ7 -> 86.647454
B42: ending balance
B43: Criminal Cases | C43: Civil cases | D43: Family Cases
A44: Republic | B44: =G5 -> 3617 | C44: =AB5 -> 3946 | D44: =AI5 -> 1083
A45: Male' | B45: =G6 -> 2409 | C45: =AB6 -> 1852 | D45: =AI6 -> 527
A46: Atoll | B46: =G7 -> 1208 | C46: =AB7 -> 2094 | D46: =AI7 -> 556
B49: concluded
B50: Criminal Cases | C50: Civil cases | D50: Family Cases
A51: Republic | B51: =F5 -> 1774 | C51: =AA5 -> 6554 | D51: =AH5 -> 5904
A52: Male' | B52: =F6 -> 1084 | C52: =AA6 -> 2719 | D52: =AH6 -> 2296
A53: Atoll | B53: =F7 -> 690 | C53: =AA7 -> 3835 | D53: =AH7 -> 3608
A55: Total
B56: Republic | C56: Male' | D56: Atolls
A57: Starting balance | B57: 7528 | C57: 4550 | D57: 2978
A58: new cases filed | B58: 15351 | C58: 6338 | D58: 9013
...

Sheet 8.18
A1: 2015 - 2002 ,udwdwAeg WycaiFwq unumcnin iawgukwtuTOkuSwr iaWaelWm : 8.18 ulwvWt
A2: Table 8.18 : CASES DEALT BY JUDICIAL COURTS IN MALE' AND ISLANDS, 2002 - 2015
A3: Court | B3: 2002 | C3: 2003 | D3: 2004 | E3: 2005 | F3: 2006 | G3: 2007 | H3: 2008 | I3: 2009 | J3: 2010 | K3: 2011 | L3: 2012 | M3: 2013 | N3: 2014 | O3: 2015 | P3: ކޯޓުތައް
A4: Total | B4: =SUM(B5:B9) -> 12390 | C4: =SUM(C5:C9) -> 11317 | D4: =SUM(D5:D9) -> 10776 | E4: =SUM(E5:E9) -> 12107 | F4: =SUM(F5:F9) -> 14084 | G4: =SUM(G5:G9) -> 13820 | H4: =SUM(H5:H9) -> 12921 | I4: =SUM(I5:I10) -> 15997 | J4: =SUM(J5:J10) -> 15036 | K4: =SUM(K5:K10) -> 14710 | L4: =SUM(L5:L10) -> 14232 | M4: =SUM(M5:M10) -> 16189 | N4: =SUM(N5:N10) -> 18902 | O4: =SUM(O5:O10) -> 18101 | P4: wlcmuj
A5: Juvenile court | B5: 136 | C5: 210 | D5: 184 | E5: 86 | F5: 154 | G5: 103 | H5: 62 | I5: 105 | J5: 211 | K5: 123 | L5: 94 | M5: 122 | N5: 81 | O5: 26 | P5: ޖުވެނައިލް ކޯޓު
A6: Family court | B6: 1302 | C6: 1332 | D6: 1401 | E6: 1865 | F6: 2034 | G6: 1981 | H6: 2032 | I6: 2089 | J6: 2044 | K6: 1996 | L6: 2194 | M6: 2590 | N6: 2616 | O6: 2553 | P6: ފެމިލީ ކޯޓު
A7: Criminal court | B7: 1700 | C7: 1071 | D7: 798 | E7: 949 | F7: 1643 | G7: 2002 | H7: 1460 | I7: 2334 | J7: 1433 | K7: 1036 | L7: 990 | M7: 1669 | N7: 1957 | O7: 1069 | P7: ކްރިމިނަލް ކޯޓު
A8: Civil court | B8: 2292 | C8: 1953 | D8: 1618 | E8: 1940 | F8: 2119 | G8: 1958 | H8: 2181 | I8: 2754 | J8: 2493 | K8: 2262 | L8: 2412 | M8: 2154 | N8: 3203 | O8: 2283 | P8: ސިވިލް ކޯޓު
A9: Magistrate Courts | B9: 6960 | C9: 6751 | D9: 6775 | E9: 7267 | F9: 8134 | G9: 7776 | H9: 7186 | I9: 8661 | J9: 8747 | K9: 9178 | L9: 8133 | M9: 9159 | N9: 10529 | O9: 12170 | P9: އަތޮޅުތަކުގައި ހުރިމެޖިސްޓްރޭޓް ކޯޓުތައް
A10: Hulhu Male' court | B10: na | C10: na | D10: na | E10: na | F10: na | G10: na | H10: na | I10: 54 | J10: 108 | K10: 115 | L10: 409 | M10: 495 | N10: 516 | P10: ހުޅުމާލެ މެޖިސްޓްރޭޓް ކޯޓު
A11: Percentage share | P11: cniawtcaws ctogWviawfiheb
